Workbook

Sheet Guida
A1: Guida — Motore Prezzi Asta Fantacalcio
A2: Questo file calcola automaticamente un prezzo massimo consigliato e un range di valutazione per ciascun giocatore, in base al budget, alla rosa, alle regole della lega e ai dati FVM/statistici. Il motore si aggiorna modificando i parametri e gli assegnamenti dell'asta.
A3: Come e' organizzato il file
A5: • Info Lega: dati della tua lega (budget, rosa, regole, nomi squadre). 'La Mia Squadra' (B28) identifica la tua squadra.
A6: • Info Strategia: modulo preferito, aggressivita' e lista 'Giocatori Preferiti' (colonna D).
A7: • Parametri Modello: tutte le leve del motore prezzi, incluse soglia minima di presenze storiche e gestione della scarsita'.
A8: • Input Giocatori 2026_27: il listone originale, invariato — e' la fonte dati.
A9: • Output Utente: tabella madre con un giocatore per riga, prezzo consigliato, range, statistiche e stato dell'asta.
A10: • Giocatori Liberi: elenco ordinato dei giocatori non ancora assegnati; il calcolo della scarsita' puo' escludere i giocatori con Qt.A=1.
A11: • La Mia Rosa: la tua rosa attuale + budget speso/rimanente + slot per ruolo, live durante l'asta.
A12: Come si calcola il prezzo (Output Utente)
A14: 1. Prezzo Base FVM = (FVM del giocatore / Somma FVM Pool Totale) × Budget Totale Lega. Il pool comprende, per ciascun ruolo, i migliori N giocatori per FVM, dove N e' il numero totale di slot di quel ruolo nella lega. Il denominatore e' la somma dei pool di tutti i ruoli.
... A33: Aggressivita': e' una preferenza dell'utente, non un parametro che il motore deve ottimizzare. Rappresenta quanto l'utente vuole spingersi verso il limite alto del range, soprattutto sui giocatori preferiti. Il motore non deve interpretare un'aggressivita' alta come una maggiore disponibilita' economica: il Max Bid dinamico resta comunque vincolato dal budget e dalla riserva minima.

Sheet Stato Asta
A1: STATO ASTA — Auction State (si aggiorna da solo mentre assegni giocatori)
A3: Giocatori chiamati / Totale listone | C3: =COUNTIFS('Output Utente'!$D$2:$D$492,"<>")&" / "&COUNTA('Output Utente'!$A$2:$A$492) -> 0 / 491
A4: % Asta completata | C4: =COUNTIFS('Output Utente'!$D$2:$D$492,"<>")/COUNTA('Output Utente'!$A$2:$A$492) -> 0
A5: Budget medio residuo squadre attive | C5: {=AVERAGE(IF('Info Lega'!$D$9:$D$24="Si",'Info Lega'!$B$4-SUMIF('Output Utente'!$D$2:$D$492,'Info Lega'!$B$9:$B$24,'Output Utente'!$M$2:$M$492)))} -> 1000
A6: Prezzo medio pagato finora (tutti i ruoli) | C6: =IFERROR(AVERAGEIF('Output Utente'!$D$2:$D$492,"<>",'Output Utente'!$M$2:$M$492),"")
A8: Ruolo | B8: Top Rimasti | C8: Buoni Rimasti | D8: Top+Buoni Rimasti | E8: Slot Ancora da Riempire (Lega) | F8: Rapporto Qualità/Slot | G8: Pressione Asta | H8: Prezzo Medio Pagato
A9: P | B9: =COUNTIFS('Output Utente'!$B$2:$B$492,"P",'Output Utente'!$P$2:$P$492,"Top",'Output Utente'!$D$2:$D$492,"") -> 9 | C9: =COUNTIFS('Output Utente'!$B$2:$B$492,"P",'Output Utente'!$P$2:$P$492,"Buono",'Output Utente'!$D$2:$D$492,"") -> 15 | D9: =$B9+$C9 -> 24 | E9: ='Parametri Modello'!$D$32 -> 24 | F9: =IFERROR($D9/$E9,"") -> 1 | G9: =IF($E9=0,"— (ruolo esaurito)",IF($F9>='Parametri Modello'!$B$46,"🟢 Puoi aspettare",IF($F9>='Parametri Modello'!$B$47,"🟡 Attesa rischiosa","🔴 Non aspettare"))) -> 🟡 Attesa rischiosa | H9: =IFERROR(AVERAGEIFS('Output Utente'!$M$2:$M$492,'Output Utente'!$B$2:$B$492,"P",'Output Utente'!$D$2:$D$492,"<>"),"")
A10: D | B10: =COUNTIFS('Output Utente'!$B$2:$B$492,"D",'Output Utente'!$P$2:$P$492,"Top",'Output Utente'!$D$2:$D$492,"") -> 30 | C10: =COUNTIFS('Output Utente'!$B$2:$B$492,"D",'Output Utente'!$P$2:$P$492,"Buono",'Output Utente'!$D$2:$D$492,"") -> 47 | D10: =$B10+$C10 -> 77 | E10: ='Parametri Modello'!$D$33 -> 64 | F10: =IFERROR($D10/$E10,"") -> 1.203125 | G10: =IF($E10=0,"— (ruolo esaurito)",IF($F10>='Parametri Modello'!$B$46,"🟢 Puoi aspettare",IF($F10>='Parametri Modello'!$B$47,"🟡 Attesa rischiosa","🔴 Non aspettare"))) -> 🟡 Attesa rischiosa | H10: =IFERROR(AVERAGEIFS('Output Utente'!$M$2:$M$492,'Output Utente'!$B$2:$B$492,"D",'Output Utente'!$D$2:$D$492,"<>"),"")
A11: C | B11: =COUNTIFS('Output Utente'!$B$2:$B$492,"C",'Output Utente'!$P$2:$P$492,"Top",'Output Utente'!$D$2:$D$492,"") -> 26 | C11: =COUNTIFS('Output Utente'!$B$2:$B$492,"C",'Output Utente'!$P$2:$P$492,"Buono",'Output Utente'!$D$2:$D$492,"") -> 44 | D11: =$B11+$C11 -> 70 | E11: ='Parametri Modello'!$D$34 -> 64 | F11: =IFERROR($D11/$E11,"") -> 1.09375 | G11: =IF($E11=0,"— (ruolo esaurito)",IF($F11>='Parametri Modello'!$B$46,"🟢 Puoi aspettare",IF($F11>='Parametri Modello'!$B$47,"🟡 Attesa rischiosa","🔴 Non aspettare"))) -> 🟡 Attesa rischiosa | H11: =IFERROR(AVERAGEIFS('Output Utente'!$M$2:$M$492,'Output Utente'!$B$2:$B$492,"C",'Output Utente'!$D$2:$D$492,"<>"),"")
A12: A | B12: =COUNTIFS('Output Utente'!$B$2:$B$492,"A",'Output Utente'!$P$2:$P$492,"Top",'Output Utente'!$D$2:$D$492,"") -> 13 | C12: =COUNTIFS('Output Utente'!$B$2:$B$492,"A",'Output Utente'!$P$2:$P$492,"Buono",'Output Utente'!$D$2:$D$492,"") -> 22 | D12: =$B12+$C12 -> 35 | E12: ='Parametri Modello'!$D$35 -> 48 | F12: =IFERROR($D12/$E12,"") -> 0.72916667 | G12: =IF($E12=0,"— (ruolo esaurito)",IF($F12>='Parametri Modello'!$B$46,"🟢 Puoi aspettare",IF($F12>='Parametri Modello'!$B$47,"🟡 Attesa rischiosa","🔴 Non aspettare"))) -> 🔴 Non aspettare | H12: =IFERROR(AVERAGEIFS('Output Utente'!$M$2:$M$492,'Output Utente'!$B$2:$B$492,"A",'Output Utente'!$D$2:$D$492,"<>"),"")
A15: Nota: Top/Buoni sono la Fascia Aspettativa di Output Utente (posizione nel FVM di ruolo), non una previsione — quindi "Top rimasti" scende man mano che chiami giocatori di quella fascia, indipendentemente da chi li compra.

Sheet Info Lega
A2: Nome Lega | B2: Lega Amici | C2: Opzionale
A3: Numero di Partecipanti | B3: 8
A4: Budget Iniziale | B4: 1000
A5: Portieri Rosa | B5: 3
A6: Difensori Rosa | B6: 8
A7: Centrocampisti Rosa | B7: 8
A8: Attaccanti Rosa | B8: 6 | D8: Attiva
A9: Nome Squadra 1 | B9: xxx1 | D9: =IF(ROW()-8<=$B$3,"Si","No") -> Si
A10: Nome Squadra 2 | B10: xxx2 | D10: =IF(ROW()-8<=$B$3,"Si","No") -> Si
A11: Nome Squadra 3 | B11: xxx3 | D11: =IF(ROW()-8<=$B$3,"Si","No") -> Si
A12: Nome Squadra 4 | B12: xxx4 | D12: =IF(ROW()-8<=$B$3,"Si","No") -> Si
A13: Nome Squadra 5 | B13: xxx5 | D13: =IF(ROW()-8<=$B$3,"Si","No") -> Si
A14: Nome Squadra 6 | B14: xxx6 | D14: =IF(ROW()-8<=$B$3,"Si","No") -> Si
A15: Nome Squadra 7 | B15: xxx7 | D15: =IF(ROW()-8<=$B$3,"Si","No") -> Si
A16: Nome Squadra 8 | B16: xxx8 | D16: =IF(ROW()-8<=$B$3,"Si","No") -> Si
A17: Nome Squadra 9 | B17: xxx9 | D17: =IF(ROW()-8<=$B$3,"Si","No") -> No
A18: Nome Squadra 10 | B18: xxx10 | D18: =IF(ROW()-8<=$B$3,"Si","No") -> No
A19: Nome Squadra 11 | B19: xxx11 | D19: =IF(ROW()-8<=$B$3,"Si","No") -> No
A20: Nome Squadra 12 | B20: xxx12 | D20: =IF(ROW()-8<=$B$3,"Si","No") -> No
... A24: Nome Squadra 16 | B24: xxx16 | D24: =IF(ROW()-8<=$B$3,"Si","No") -> No
A25: Modificatore Difesa | B25: Si
A26: Modificatore Centrocampo | B26: No
A27: Regole chiamata giocatori | B27: A Chiamata Libera
A28: La Mia Squadra | B28: xxx1 | C28: Seleziona il tuo nome squadra dalla lista sopra (B9:B24)

Sheet Info Strategia
A1: Modulo Preferito | B1: 3-4-3 | D1: Lista Giocatori Preferiti (nome esatto come in Input Giocatori)
A2: D | B2: =MID(B1,1,1) -> 3
A3: C | B3: =MID(B1,3,1) -> 4
A4: A | B4: =MID(B1,5,1) -> 3
A5: Giocatori Preferiti
A6: Aggressivita | B6: 0.7

Sheet Input Giocatori 2026_27
A1: Quotazioni Fantacalcio Stagione 2026 27
A2: Id | B2: R | C2: Nome | D2: Squadra | E2: Qt.A | F2: Qt.I | G2: FVM/1000
A3: 5841 | B3: P | C3: Svilar | D3: Roma | E3: 18 | F3: 18 | G3: 65
A4: 5116 | B4: P | C4: Martinez Jo. | D4: Inter | E4: 17 | F4: 17 | G4: 63
A5: 4431 | B5: P | C5: Carnesecchi | D5: Atalanta | E5: 16 | F5: 16 | G5: 52
A6: 6966 | B6: P | C6: Butez | D6: Como | E6: 16 | F6: 16 | G6: 56
A7: 4312 | B7: P | C7: Maignan | D7: Milan | E7: 15 | F7: 15 | G7: 50
A8: 2521 | B8: P | C8: De Gea | D8: Fiorentina | E8: 13 | F8: 13 | G8: 45
A9: 572 | B9: P | C9: Meret | D9: Napoli | E9: 11 | F9: 11 | G9: 45
A10: 133 | B10: P | C10: Skorupski | D10: Bologna | E10: 10 | F10: 10 | G10: 37
A11: 4360 | B11: P | C11: Caprile | D11: Cagliari | E11: 9 | F11: 9 | G11: 27
A12: 5876 | B12: P | C12: Di Gregorio | D12: Juventus | E12: 9 | F12: 9 | G12: 40
A13: 6482 | B13: P | C13: Mandas | D13: Lazio | E13: 9 | F13: 9 | G13: 30
A14: 6462 | B14: P | C14: Okoye | D14: Udinese | E14: 9 | F14: 9 | G14: 29
... A493: 7482 | B493: A | C493: Lauberbach | D493: Venezia | E493: 1 | F493: 1 | G493: 1

Sheet Output Utente
A1: Id | B1: R | C1: Nome | D1: Squadra Assegnata | E1: Whichlist | F1: Offerta Max | G1: Valutazione Min | H1: Valutazione Max | I1: Presenze 25/26 (Pv) | J1: Assenze 25/26 (stim.) | K1: Gol 25/26 | L1: Assist 25/26 | M1: Prezzo Pagato | N1: Qt.A | O1: FVM/1000 | P1: Fascia Aspettativa | Q1: _OrdineLiberi | R1: _OrdineMiaRosa | S1: Mv 25/26 | T1: Fm 25/26 | U1: Sostenibilità Budget | V1: Rank FVM nel Ruolo | W1: Budget Residuo | X1: Slot Residui | Y1: Budget Minimo Riserva | Z1: Budget Spendibile | AA1: Offerta Max Dinamica | AB1: Prezzo Corrente | AC1: Decisione Live | AD1: Confidence Storico | AE1: Pressione Ruolo
A2: 2764 | B2: A | C2: Martinez L. | E2: =IF(COUNTIF('Info Strategia'!$D$2:$D$51,$C2)>0,"SI","NO") -> NO | F2: =IFERROR(ROUND(($G2+($H2-$G2)*'Info Strategia'!$B$6)*(1+IF($E2="SI",'Parametri Modello'!$B$7*'Info Strategia'!$B$6,0)),0),"") -> 397 | G2: =IFERROR(ROUND(MAX(1,(IF($V2<=INDEX('Parametri Modello'!$C$57:$C$60,MATCH($B2,'Parametri Modello'!$A$57:$A$60,0)),IF(INDEX('Parametri Modello'!$E$57:$E$60,MATCH($B2,'Parametri Modello'!$A$57:$A$60,0))=0,0,($O2/INDEX('Parametri Modello'!$E$57:$E$60,MATCH($B2,'Parametri Modello'!$A$57:$A$60,0)))*(INDEX('Parametri Modello'!$D$57:$D$60,MATCH($B2,'Parametri Modello'!$A$57:$A$60,0))*(INDEX('Parametri Modello'!$B$50:$B$53,MATCH($B2,'Parametri Modello'!$A$50:$A$53,0))*'Parametri Modello'!$B$44))),IF(INDEX('Parametri Modello'!$F$57:$F$60,MATCH($B2,'Parametri Modello'!$A$57:$A$60,0))=0,0,($O2/INDEX('Parametri Modello'!$F$57:$F$60,MATCH($B2,'Parametri Modello'!$A$57:$A$60,0)))*((1-INDEX('Parametri Modello'!$D$57:$D$60,MATCH($B2,'Parametri Modello'!$A$57:$A$60,0)))*(INDEX('Parametri Modello'!$B$50:$B$53,MATCH($B2,'Parametri Modello'!$A$50:$A$53,0))*'Parametri Modello'!$B$44))))*(1+IF(IF($B2="D",'Info Lega'!$B$25,IF($B2="C",'Info Lega'!$B$26,"No"))="Si",'Parametri Modello'!$B$5,0))*(1+MAX(-0.25,MIN(0.25,IF(OR($T2="",$I2="",$I2=0,INDEX('Parametri Modello'!$B$19:$B$22,MATCH($B2,'Parametri Modello'!$A$19:$A$22,0))="",INDEX('Parametri Modello'!$B$19:$B$22,MATCH($B2,'Parametri Modello'!$A$19:$A$22,0))=0),0,(($T2-INDEX('Parametri Modello'!$B$19:$B$22,MATCH($B2,'Parametri Modello'!$A$19:$A$22,0)))/INDEX('Parametri Modello'!$B$19:$B$22,MATCH($B2,'Parametri Modello'!$A$19:$A$22,0)))*'Parametri Modello'!$B$9))))*(1+IF('Parametri Modello'!$B$27="Si",MAX(-'Parametri Modello'!$B$28,MIN('Parametri Modello'!$B$28*1.5,IF(OR(INDEX('Parametri Modello'!$F$32:$F$35,MATCH($B2,'Parametri Modello'!$A$32:$A$35,0))="",INDEX('Parametri Modello'!$F$32:$F$35,MATCH($B2,'Parametri Modello'!$A$32:$A$35,0))=0),0,(1/INDEX('Parametri Modello'!$F$32:$F$35,MATCH($B2,'Parametri Modello'!$A$32:$A$35,0))-1)*'Parametri Modello'!$B$28))),0)))*(1-INDEX('Parametri Modello'!$B$12:$B$15,MATCH($B2,'Parametri Modello'!$A$12:$A$15,0)))),0),"") -> 248 | H2: =IFERROR(ROUND((IF($V2<=INDEX('Parametri Modello'!$C$57:$C$60,MATCH($B2,'Parametri Modello'!$A$57:$A$60,0)),IF(INDEX('Parametri Modello'!$E$57:$E$60,MATCH($B2,'Parametri Modello'!$A$57:$A$60,0))=0,0,($O2/INDEX('Parametri Modello'!$E$57:$E$60,MATCH($B2,'Parametri Modello'!$A$57:$A$60,0)))*(INDEX('Parametri Modello'!$D$57:$D$60,MATCH($B2,'Parametri Modello'!$A$57:$A$60,0))*(INDEX('Parametri Modello'!$B$50:$B$53,MATCH($B2,'Parametri Modello'!$A$50:$A$53,0))*'Parametri Modello'!$B$44))),IF(INDEX('Parametri Modello'!$F$57:$F$60,MATCH($B2,'Parametri Modello'!$A$57:$A$60,0))=0,0,($O2/INDEX('Parametri Modello'!$F$57:$F$60,MATCH($B2,'Parametri Modello'!$A$57:$A$60,0)))*((1-INDEX('Parametri Modello'!$D$57:$D$60,MATCH($B2,'Parametri Modello'!$A$57:$A$60,0)))*(INDEX('Parametri Modello'!$B$50:$B$53,MATCH($B2,'Parametri Modello'!$A$50:$A$53,0))*'Parametri Modello'!$B$44))))*(1+IF(IF($B2="D",'Info Lega'!$B$25,IF($B2="C",'Info Lega'!$B$26,"No"))="Si",'Parametri Modello'!$B$5,0))*(1+MAX(-0.25,MIN(0.25,IF(OR($T2="",$I2="",$I2=0,INDEX('Parametri Modello'!$B$19:$B$22,MATCH($B2,'Parametri Modello'!$A$19:$A$22,0))="",INDEX('Parametri Modello'!$B$19:$B$22,MATCH($B2,'Parametri Modello'!$A$19:$A$22,0))=0),0,(($T2-INDEX('Parametri Modello'!$B$19:$B$22,MATCH($B2,'Parametri Modello'!$A$19:$A$22,0)))/INDEX('Parametri Modello'!$B$19:$B$22,MATCH($B2,'Parametri Modello'!$A$19:$A$22,0)))*'Parametri Modello'!$B$9))))*(1+IF('Parametri Modello'!$B$27="Si",MAX(-'Parametri Modello'!$B$28,MIN('Parametri Modello'!$B$28*1.5,IF(OR(INDEX('Parametri Modello'!$F$32:$F$35,MATCH($B2,'Parametri Modello'!$A$32:$A$35,0))="",INDEX('Parametri Modello'!$F$32:$F$35,MATCH($B2,'Parametri Modello'!$A$32:$A$35,0))=0),0,(1/INDEX('Parametri Modello'!$F$32:$F$35,MATCH($B2,'Parametri Modello'!$A$32:$A$35,0))-1)*'Parametri Modello'!$B$28))),0)))*(1+INDEX('Parametri Modello'!$B$12:$B$15,MATCH($B2,'Parametri Modello'!$A$12:$A$15,0))),0),"") -> 461 | I2: =IFERROR(INDEX('Input Statistiche 2025_26'!$F$3:$F$665,MATCH($A2,'Input Statistiche 2025_26'!$A$3:$A$665,0)),"") -> 30 | J2: =IFERROR(IF($I2="","",MAX(0,38-$I2)),"") -> 8 | K2: =IFERROR(INDEX('Input Statistiche 2025_26'!$I$3:$I$665,MATCH($A2,'Input Statistiche 2025_26'!$A$3:$A$665,0)),"") -> 17 | L2: =IFERROR(INDEX('Input Statistiche 2025_26'!$O$3:$O$665,MATCH($A2,'Input Statistiche 2025_26'!$A$3:$A$665,0)),"") -> 6 | N2: =IFERROR(INDEX('Input Giocatori 2026_27'!$E$3:$E$493,MATCH($A2,'Input Giocatori 2026_27'!$A$3:$A$493,0)),"") -> 35 | O2: =IFERROR(INDEX('Input Giocatori 2026_27'!$G$3:$G$493,MATCH($A2,'Input Giocatori 2026_27'!$A$3:$A$493,0)),"") -> 370 | P2: =IFERROR(IF($O2="","",IF((1-(COUNTIFS($B$2:$B$492,$B2,$O$2:$O$492,">"&$O2)+1-1)/COUNTIF($B$2:$B$492,$B2))>=0.85,"Top",IF((1-(COUNTIFS($B$2:$B$492,$B2,$O$2:$O$492,">"&$O2)+1-1)/COUNTIF($B$2:$B$492,$B2))>=0.6,"Buono",IF((1-(COUNTIFS($B$2:$B$492,$B2,$O$2:$O$492,">"&$O2)+1-1)/COUNTIF($B$2:$B$492,$B2))>=0.3,"Nella Media","Scommessa/Riserva")))),"") -> Top | Q2: =IF($D2="",COUNTIF($D$2:$D2,""),"") -> 1 | R2: =IF($D2='Info Lega'!$B$28,COUNTIFS($D$2:$D2,'Info Lega'!$B$28),"") | S2: =IFERROR(INDEX('Input Statistiche 2025_26'!$G$3:$G$665,MATCH($A2,'Input Statistiche 2025_26'!$A$3:$A$665,0)),"") -> 6.42 | T2: =IFERROR(INDEX('Input Statistiche 2025_26'!$H$3:$H$665,MATCH($A2,'Input Statistiche 2025_26'!$A$3:$A$665,0)),"") -> 8.25 | U2: =IF(OR('La Mia Rosa'!$O$12="",$D2<>""),"",IF($F2<='La Mia Rosa'!$O$12*'Parametri Modello'!$B$24,"OK",IF($F2<='La Mia Rosa'!$O$12*'Parametri Modello'!$B$25,"Attenzione","Rischio Alto"))) -> Rischio Alto | V2: =IFERROR(COUNTIFS($B$2:$B$492,$B2,$O$2:$O$492,">"&$O2)+1,"") -> 1 | W2: ='Info Lega'!$B$4-SUMIFS($M$2:$M$492,$D$2:$D$492,'Info Lega'!$B$28) -> 1000 | X2: =('Info Lega'!$B$5-COUNTIFS($D$2:$D$492,'Info Lega'!$B$28,$B$2:$B$492,"P"))+('Info Lega'!$B$6-COUNTIFS($D$2:$D$492,'Info Lega'!$B$28,$B$2:$B$492,"D"))+('Info Lega'!$B$7-COUNTIFS($D$2:$D$492,'Info Lega'!$B$28,$B$2:$B$492,"C"))+('Info Lega'!$B$8-COUNTIFS($D$2:$D$492,'Info Lega'!$B$28,$B$2:$B$492,"A")) -> 25 | Y2: =X2*'Parametri Modello'!$B$30 -> 25 | Z2: =MAX(0,W2-Y2) -> 975 | AA2: =MIN(F2,Z2) -> 397 | AC2: =IF(AB2="","",IF(AB2>AA2,"PASS",IF(AB2<=AA2*0.85,"BID","ATTENZIONE"))) | AD2: =IF(I2="","",ROUND(100*(1-EXP(-I2/30)),0)) -> 63 | AE2: =IFERROR(INDEX('Stato Asta'!$G$9:$G$12,MATCH($B2,'Stato Asta'!$A$9:$A$12,0)),"") -> 🔴 Non aspettare
A3: 5585 | B3: A | C3: Malen | E3: =IF(COUNTIF('Info Strategia'!$D$2:$D$51,$C3)>0,"SI","NO") -> NO | F3: =IFERROR(ROUND(($G3+($H3-$G3)*'Info Strategia'!$B$6)*(1+IF($E3="SI",'Parametri Modello'!$B$7*'Info Strategia'!$B$6,0)),0),"") -> 400 | G3: =IFERROR(ROUND(MAX(1,(IF($V3<=INDEX('Parametri Modello'!$C$57:$C$60,MATCH($B3,'Parametri Modello'!$A$57:$A$60,0)),IF(INDEX('Parametri Modello'!$E$57:$E$60,MATCH($B3,'Parametri Modello'!$A$57:$A$60,0))=0,0,($O3/INDEX('Parametri Modello'!$E$57:$E$60,MATCH($B3,'Parametri Modello'!$A$57:$A$60,0)))*(INDEX('Parametri Modello'!$D$57:$D$60,MATCH($B3,'Parametri Modello'!$A$57:$A$60,0))*(INDEX('Parametri Modello'!$B$50:$B$53,MATCH($B3,'Parametri Modello'!$A$50:$A$53,0))*'Parametri Modello'!$B$44))),IF(INDEX('Parametri Modello'!$F$57:$F$60,MATCH($B3,'Parametri Modello'!$A$57:$A$60,0))=0,0,($O3/INDEX('Parametri Modello'!$F$57:$F$60,MATCH($B3,'Parametri Modello'!$A$57:$A$60,0)))*((1-INDEX('Parametri Modello'!$D$57:$D$60,MATCH($B3,'Parametri Modello'!$A$57:$A$60,0)))*(INDEX('Parametri Modello'!$B$50:$B$53,MATCH($B3,'Parametri Modello'!$A$50:$A$53,0))*'Parametri Modello'!$B$44))))*(1+IF(IF($B3="D",'Info Lega'!$B$25,IF($B3="C",'Info Lega'!$B$26,"No"))="Si",'Parametri Modello'!$B$5,0))*(1+MAX(-0.25,MIN(0.25,IF(OR($T3="",$I3="",$I3=0,INDEX('Parametri Modello'!$B$19:$B$22,MATCH($B3,'Parametri Modello'!$A$19:$A$22,0))="",INDEX('Parametri Modello'!$B$19:$B$22,MATCH($B3,'Parametri Modello'!$A$19:$A$22,0))=0),0,(($T3-INDEX('Parametri Modello'!$B$19:$B$22,MATCH($B3,'Parametri Modello'!$A$19:$A$22,0)))/INDEX('Parametri Modello'!$B$19:$B$22,MATCH($B3,'Parametri Modello'!$A$19:$A$22,0)))*'Parametri Modello'!$B$9))))*(1+IF('Parametri Modello'!$B$27="Si",MAX(-'Parametri Modello'!$B$28,MIN('Parametri Modello'!$B$28*1.5,IF(OR(INDEX('Parametri Modello'!$F$32:$F$35,MATCH($B3,'Parametri Modello'!$A$32:$A$35,0))="",INDEX('Parametri Modello'!$F$32:$F$35,MATCH($B3,'Parametri Modello'!$A$32:$A$35,0))=0),0,(1/INDEX('Parametri Modello'!$F$32:$F$35,MATCH($B3,'Parametri Modello'!$A$32:$A$35,0))-1)*'Parametri Modello'!$B$28))),0)))*(1-INDEX('Parametri Modello'!$B$12:$B$15,MATCH($B3,'Parametri Modello'!$A$12:$A$15,0)))),0),"") -> 250 | H3: =IFERROR(ROUND((IF($V3<=INDEX('Parametri Modello'!$C$57:$C$60,MATCH($B3,'Parametri Modello'!$A$57:$A$60,0)),IF(INDEX('Parametri Modello'!$E$57:$E$60,MATCH($B3,'Parametri Modello'!$A$57:$A$60,0))=0,0,($O3/INDEX('Parametri Modello'!$E$57:$E$60,MATCH($B3,'Parametri Modello'!$A$57:$A$60,0)))*(INDEX('Parametri Modello'!$D$57:$D$60,MATCH($B3,'Parametri Modello'!$A$57:$A$60,0))*(INDEX('Parametri Modello'!$B$50:$B$53,MATCH($B3,'Parametri Modello'!$A$50:$A$53,0))*'Parametri Modello'!$B$44))),IF(INDEX('Parametri Modello'!$F$57:$F$60,MATCH($B3,'Parametri Modello'!$A$57:$A$60,0))=0,0,($O3/INDEX('Parametri Modello'!$F$57:$F$60,MATCH($B3,'Parametri Modello'!$A$57:$A$60,0)))*((1-INDEX('Parametri Modello'!$D$57:$D$60,MATCH($B3,'Parametri Modello'!$A$57:$A$60,0)))*(INDEX('Parametri Modello'!$B$50:$B$53,MATCH($B3,'Parametri Modello'!$A$50:$A$53,0))*'Parametri Modello'!$B$44))))*(1+IF(IF($B3="D",'Info Lega'!$B$25,IF($B3="C",'Info Lega'!$B$26,"No"))="Si",'Parametri Modello'!$B$5,0))*(1+MAX(-0.25,MIN(0.25,IF(OR($T3="",$I3="",$I3=0,INDEX('Parametri Modello'!$B$19:$B$22,MATCH($B3,'Parametri Modello'!$A$19:$A$22,0))="",INDEX('Parametri Modello'!$B$19:$B$22,MATCH($B3,'Parametri Modello'!$A$19:$A$22,0))=0),0,(($T3-INDEX('Parametri Modello'!$B$19:$B$22,MATCH($B3,'Parametri Modello'!$A$19:$A$22,0)))/INDEX('Parametri Modello'!$B$19:$B$22,MATCH($B3,'Parametri Modello'!$A$19:$A$22,0)))*'Parametri Modello'!$B$9))))*(1+IF('Parametri Modello'!$B$27="Si",MAX(-'Parametri Modello'!$B$28,MIN('Parametri Modello'!$B$28*1.5,IF(OR(INDEX('Parametri Modello'!$F$32:$F$35,MATCH($B3,'Parametri Modello'!$A$32:$A$35,0))="",INDEX('Parametri Modello'!$F$32:$F$35,MATCH($B3,'Parametri Modello'!$A$32:$A$35,0))=0),0,(1/INDEX('Parametri Modello'!$F$32:$F$35,MATCH($B3,'Parametri Modello'!$A$32:$A$35,0))-1)*'Parametri Modello'!$B$28))),0)))*(1+INDEX('Parametri Modello'!$B$12:$B$15,MATCH($B3,'Parametri Modello'!$A$12:$A$15,0))),0),"") -> 464 | I3: =IFERROR(INDEX('Input Statistiche 2025_26'!$F$3:$F$665,MATCH($A3,'Input Statistiche 2025_26'!$A$3:$A$665,0)),"") -> 18 | J3: =IFERROR(IF($I3="","",MAX(0,38-$I3)),"") -> 20 | K3: =IFERROR(INDEX('Input Statistiche 2025_26'!$I$3:$I$665,MATCH($A3,'Input Statistiche 2025_26'!$A$3:$A$665,0)),"") -> 14 | L3: =IFERROR(INDEX('Input Statistiche 2025_26'!$O$3:$O$665,MATCH($A3,'Input Statistiche 2025_26'!$A$3:$A$665,0)),"") -> 2 | N3: =IFERROR(INDEX('Input Giocatori 2026_27'!$E$3:$E$493,MATCH($A3,'Input Giocatori 2026_27'!$A$3:$A$493,0)),"") -> 34 | O3: =IFERROR(INDEX('Input Giocatori 2026_27'!$G$3:$G$493,MATCH($A3,'Input Giocatori 2026_27'!$A$3:$A$493,0)),"") -> 365 | P3: =IFERROR(IF($O3="","",IF((1-(COUNTIFS($B$2:$B$492,$B3,$O$2:$O$492,">"&$O3)+1-1)/COUNTIF($B$2:$B$492,$B3))>=0.85,"Top",IF((1-(COUNTIFS($B$2:$B$492,$B3,$O$2:$O$492,">"&$O3)+1-1)/COUNTIF($B$2:$B$492,$B3))>=0.6,"Buono",IF((1-(COUNTIFS($B$2:$B$492,$B3,$O$2:$O$492,">"&$O3)+1-1)/COUNTIF($B$2:$B$492,$B3))>=0.3,"Nella Media","Scommessa/Riserva")))),"") -> Top | Q3: =IF($D3="",COUNTIF($D$2:$D3,""),"") -> 2 | R3: =IF($D3='Info Lega'!$B$28,COUNTIFS($D$2:$D3,'Info Lega'!$B$28),"") | S3: =IFERROR(INDEX('Input Statistiche 2025_26'!$G$3:$G$665,MATCH($A3,'Input Statistiche 2025_26'!$A$3:$A$665,0)),"") -> 6.72 | T3: =IFERROR(INDEX('Input Statistiche 2025_26'!$H$3:$H$665,MATCH($A3,'Input Statistiche 2025_26'!$A$3:$A$665,0)),"") -> 8.97 | U3: =IF(OR('La Mia Rosa'!$O$12="",$D3<>""),"",IF($F3<='La Mia Rosa'!$O$12*'Parametri Modello'!$B$24,"OK",IF($F3<='La Mia Rosa'!$O$12*'Parametri Modello'!$B$25,"Attenzione","Rischio Alto"))) -> Rischio Alto | V3: =IFERROR(COUNTIFS($B$2:$B$492,$B3,$O$2:$O$492,">"&$O3)+1,"") -> 2 | W3: ='Info Lega'!$B$4-SUMIFS($M$2:$M$492,$D$2:$D$492,'Info Lega'!$B$28) -> 1000 | X3: =('Info Lega'!$B$5-COUNTIFS($D$2:$D$492,'Info Lega'!$B$28,$B$2:$B$492,"P"))+('Info Lega'!$B$6-COUNTIFS($D$2:$D$492,'Info Lega'!$B$28,$B$2:$B$492,"D"))+('Info Lega'!$B$7-COUNTIFS($D$2:$D$492,'Info Lega'!$B$28,$B$2:$B$492,"C"))+('Info Lega'!$B$8-COUNTIFS($D$2:$D$492,'Info Lega'!$B$28,$B$2:$B$492,"A")) -> 25 | Y3: =X3*'Parametri Modello'!$B$30 -> 25 | Z3: =MAX(0,W3-Y3) -> 975 | AA3: =MIN(F3,Z3) -> 400 | AC3: =IF(AB3="","",IF(AB3>AA3,"PASS",IF(AB3<=AA3*0.85,"BID","ATTENZIONE"))) | AD3: =IF(I3="","",ROUND(100*(1-EXP(-I3/30)),0)) -> 45 | AE3: =IFERROR(INDEX('Stato Asta'!$G$9:$G$12,MATCH($B3,'Stato Asta'!$A$9:$A$12,0)),"") -> 🔴 Non aspettare
A4: 4871 | B4: A | C4: Thuram | E4: =IF(COUNTIF('Info Strategia'!$D$2:$D$51,$C4)>0,"SI","NO") -> NO | F4: =IFERROR(ROUND(($G4+($H4-$G4)*'Info Strategia'!$B$6)*(1+IF($E4="SI",'Parametri Modello'!$B$7*'Info Strategia'!$B$6,0)),0),"") -> 298 | G4: =IFERROR(ROUND(MAX(1,(IF($V4<=INDEX('Parametri Modello'!$C$57:$C$60,MATCH($B4,'Parametri Modello'!$A$57:$A$60,0)),IF(INDEX('Parametri Modello'!$E$57:$E$60,MATCH($B4,'Parametri Modello'!$A$57:$A$60,0))=0,0,($O4/INDEX('Parametri Modello'!$E$57:$E$60,MATCH($B4,'Parametri Modello'!$A$57:$A$60,0)))*(INDEX('Parametri Modello'!$D$57:$D$60,MATCH($B4,'Parametri Modello'!$A$57:$A$60,0))*(INDEX('Parametri Modello'!$B$50:$B$53,MATCH($B4,'Parametri Modello'!$A$50:$A$53,0))*'Parametri Modello'!$B$44))),IF(INDEX('Parametri Modello'!$F$57:$F$60,MATCH($B4,'Parametri Modello'!$A$57:$A$60,0))=0,0,($O4/INDEX('Parametri Modello'!$F$57:$F$60,MATCH($B4,'Parametri Modello'!$A$57:$A$60,0)))*((1-INDEX('Parametri Modello'!$D$57:$D$60,MATCH($B4,'Parametri Modello'!$A$57:$A$60,0)))*(INDEX('Parametri Modello'!$B$50:$B$53,MATCH($B4,'Parametri Modello'!$A$50:$A$53,0))*'Parametri Modello'!$B$44))))*(1+IF(IF($B4="D",'Info Lega'!$B$25,IF($B4="C",'Info Lega'!$B$26,"No"))="Si",'Parametri Modello'!$B$5,0))*(1+MAX(-0.25,MIN(0.25,IF(OR($T4="",$I4="",$I4=0,INDEX('Parametri Modello'!$B$19:$B$22,MATCH($B4,'Parametri Modello'!$A$19:$A$22,0))="",INDEX('Parametri Modello'!$B$19:$B$22,MATCH($B4,'Parametri Modello'!$A$19:$A$22,0))=0),0,(($T4-INDEX('Parametri Modello'!$B$19:$B$22,MATCH($B4,'Parametri Modello'!$A$19:$A$22,0)))/INDEX('Parametri Modello'!$B$19:$B$22,MATCH($B4,'Parametri Modello'!$A$19:$A$22,0)))*'Parametri Modello'!$B$9))))*(1+IF('Parametri Modello'!$B$27="Si",MAX(-'Parametri Modello'!$B$28,MIN('Parametri Modello'!$B$28*1.5,IF(OR(INDEX('Parametri Modello'!$F$32:$F$35,MATCH($B4,'Parametri Modello'!$A$32:$A$35,0))="",INDEX('Parametri Modello'!$F$32:$F$35,MATCH($B4,'Parametri Modello'!$A$32:$A$35,0))=0),0,(1/INDEX('Parametri Modello'!$F$32:$F$35,MATCH($B4,'Parametri Modello'!$A$32:$A$35,0))-1)*'Parametri Modello'!$B$28))),0)))*(1-INDEX('Parametri Modello'!$B$12:$B$15,MATCH($B4,'Parametri Modello'!$A$12:$A$15,0)))),0),"") -> 186 | H4: =IFERROR(ROUND((IF($V4<=INDEX('Parametri Modello'!$C$57:$C$60,MATCH($B4,'Parametri Modello'!$A$57:$A$60,0)),IF(INDEX('Parametri Modello'!$E$57:$E$60,MATCH($B4,'Parametri Modello'!$A$57:$A$60,0))=0,0,($O4/INDEX('Parametri Modello'!$E$57:$E$60,MATCH($B4,'Parametri Modello'!$A$57:$A$60,0)))*(INDEX('Parametri Modello'!$D$57:$D$60,MATCH($B4,'Parametri Modello'!$A$57:$A$60,0))*(INDEX('Parametri Modello'!$B$50:$B$53,MATCH($B4,'Parametri Modello'!$A$50:$A$53,0))*'Parametri Modello'!$B$44))),IF(INDEX('Parametri Modello'!$F$57:$F$60,MATCH($B4,'Parametri Modello'!$A$57:$A$60,0))=0,0,($O4/INDEX('Parametri Modello'!$F$57:$F$60,MATCH($B4,'Parametri Modello'!$A$57:$A$60,0)))*((1-INDEX('Parametri Modello'!$D$57:$D$60,MATCH($B4,'Parametri Modello'!$A$57:$A$60,0)))*(INDEX('Parametri Modello'!$B$50:$B$53,MATCH($B4,'Parametri Modello'!$A$50:$A$53,0))*'Parametri Modello'!$B$44))))*(1+IF(IF($B4="D",'Info Lega'!$B$25,IF($B4="C",'Info Lega'!$B$26,"No"))="Si",'Parametri Modello'!$B$5,0))*(1+MAX(-0.25,MIN(0.25,IF(OR($T4="",$I4="",$I4=0,INDEX('Parametri Modello'!$B$19:$B$22,MATCH($B4,'Parametri Modello'!$A$19:$A$22,0))="",INDEX('Parametri Modello'!$B$19:$B$22,MATCH($B4,'Parametri Modello'!$A$19:$A$22,0))=0),0,(($T4-INDEX('Parametri Modello'!$B$19:$B$22,MATCH($B4,'Parametri Modello'!$A$19:$A$22,0)))/INDEX('Parametri Modello'!$B$19:$B$22,MATCH($B4,'Parametri Modello'!$A$19:$A$22,0)))*'Parametri Modello'!$B$9))))*(1+IF('Parametri Modello'!$B$27="Si",MAX(-'Parametri Modello'!$B$28,MIN('Parametri Modello'!$B$28*1.5,IF(OR(INDEX('Parametri Modello'!$F$32:$F$35,MATCH($B4,'Parametri Modello'!$A$32:$A$35,0))="",INDEX('Parametri Modello'!$F$32:$F$35,MATCH($B4,'Parametri Modello'!$A$32:$A$35,0))=0),0,(1/INDEX('Parametri Modello'!$F$32:$F$35,MATCH($B4,'Parametri Modello'!$A$32:$A$35,0))-1)*'Parametri Modello'!$B$28))),0)))*(1+INDEX('Parametri Modello'!$B$12:$B$15,MATCH($B4,'Parametri Modello'!$A$12:$A$15,0))),0),"") -> 346 | I4: =IFERROR(INDEX('Input Statistiche 2025_26'!$F$3:$F$665,MATCH($A4,'Input Statistiche 2025_26'!$A$3:$A$665,0)),"") -> 29 | J4: =IFERROR(IF($I4="","",MAX(0,38-$I4)),"") -> 9 | K4: =IFERROR(INDEX('Input Statistiche 2025_26'!$I$3:$I$665,MATCH($A4,'Input Statistiche 2025_26'!$A$3:$A$665,0)),"") -> 13 | L4: =IFERROR(INDEX('Input Statistiche 2025_26'!$O$3:$O$665,MATCH($A4,'Input Statistiche 2025_26'!$A$3:$A$665,0)),"") -> 6 | N4: =IFERROR(INDEX('Input Giocatori 2026_27'!$E$3:$E$493,MATCH($A4,'Input Giocatori 2026_27'!$A$3:$A$493,0)),"") -> 29 | O4: =IFERROR(INDEX('Input Giocatori 2026_27'!$G$3:$G$493,MATCH($A4,'Input Giocatori 2026_27'!$A$3:$A$493,0)),"") -> 280 | P4: =IFERROR(IF($O4="","",IF((1-(COUNTIFS($B$2:$B$492,$B4,$O$2:$O$492,">"&$O4)+1-1)/COUNTIF($B$2:$B$492,$B4))>=0.85,"Top",IF((1-(COUNTIFS($B$2:$B$492,$B4,$O$2:$O$492,">"&$O4)+1-1)/COUNTIF($B$2:$B$492,$B4))>=0.6,"Buono",IF((1-(COUNTIFS($B$2:$B$492,$B4,$O$2:$O$492,">"&$O4)+1-1)/COUNTIF($B$2:$B$492,$B4))>=0.3,"Nella Media","Scommessa/Riserva")))),"") -> Top | Q4: =IF($D4="",COUNTIF($D$2:$D4,""),"") -> 3 | R4: =IF($D4='Info Lega'!$B$28,COUNTIFS($D$2:$D4,'Info Lega'!$B$28),"") | S4: =IFERROR(INDEX('Input Statistiche 2025_26'!$G$3:$G$665,MATCH($A4,'Input Statistiche 2025_26'!$A$3:$A$665,0)),"") -> 6.43 | T4: =IFERROR(INDEX('Input Statistiche 2025_26'!$H$3:$H$665,MATCH($A4,'Input Statistiche 2025_26'!$A$3:$A$665,0)),"") -> 7.95 | U4: =IF(OR('La Mia Rosa'!$O$12="",$D4<>""),"",IF($F4<='La Mia Rosa'!$O$12*'Parametri Modello'!$B$24,"OK",IF($F4<='La Mia Rosa'!$O$12*'Parametri Modello'!$B$25,"Attenzione","Rischio Alto"))) -> Rischio Alto | V4: =IFERROR(COUNTIFS($B$2:$B$492,$B4,$O$2:$O$492,">"&$O4)+1,"") -> 3 | W4: ='Info Lega'!$B$4-SUMIFS($M$2:$M$492,$D$2:$D$492,'Info Lega'!$B$28) -> 1000 | X4: =('Info Lega'!$B$5-COUNTIFS($D$2:$D$492,'Info Lega'!$B$28,$B$2:$B$492,"P"))+('Info Lega'!$B$6-COUNTIFS($D$2:$D$492,'Info Lega'!$B$28,$B$2:$B$492,"D"))+('Info Lega'!$B$7-COUNTIFS($D$2:$D$492,'Info Lega'!$B$28,$B$2:$B$492,"C"))+('Info Lega'!$B$8-COUNTIFS($D$2:$D$492,'Info Lega'!$B$28,$B$2:$B$492,"A")) -> 25 | Y4: =X4*'Parametri Modello'!$B$30 -> 25 | Z4: =MAX(0,W4-Y4) -> 975 | AA4: =MIN(F4,Z4) -> 298 | AC4: =IF(AB4="","",IF(AB4>AA4,"PASS",IF(AB4<=AA4*0.85,"BID","ATTENZIONE"))) | AD4: =IF(I4="","",ROUND(100*(1-EXP(-I4/30)),0)) -> 62 | AE4: =IFERROR(INDEX('Stato Asta'!$G$9:$G$12,MATCH($B4,'Stato Asta'!$A$9:$A$12,0)),"") -> 🔴 Non aspettare
A5: 6052 | B5: A | C5: Hojlund | E5: =IF(COUNTIF('Info Strategia'!$D$2:$D$51,$C5)>0,"SI","NO") -> NO | F5: =IFERROR(ROUND(($G5+($H5-$G5)*'Info Strategia'!$B$6)*(1+IF($E5="SI",'Parametri Modello'!$B$7*'Info Strategia'!$B$6,0)),0),"") -> 284 | G5: =IFERROR(ROUND(MAX(1,(IF($V5<=INDEX('Parametri Modello'!$C$57:$C$60,MATCH($B5,'Parametri Modello'!$A$57:$A$60,0)),IF(INDEX('Parametri Modello'!$E$57:$E$60,MATCH($B5,'Parametri Modello'!$A$57:$A$60,0))=0,0,($O5/INDEX('Parametri Modello'!$E$57:$E$60,MATCH($B5,'Parametri Modello'!$A$57:$A$60,0)))*(INDEX('Parametri Modello'!$D$57:$D$60,MATCH($B5,'Parametri Modello'!$A$57:$A$60,0))*(INDEX('Parametri Modello'!$B$50:$B$53,MATCH($B5,'Parametri Modello'!$A$50:$A$53,0))*'Parametri Modello'!$B$44))),IF(INDEX('Parametri Modello'!$F$57:$F$60,MATCH($B5,'Parametri Modello'!$A$57:$A$60,0))=0,0,($O5/INDEX('Parametri Modello'!$F$57:$F$60,MATCH($B5,'Parametri Modello'!$A$57:$A$60,0)))*((1-INDEX('Parametri Modello'!$D$57:$D$60,MATCH($B5,'Parametri Modello'!$A$57:$A$60,0)))*(INDEX('Parametri Modello'!$B$50:$B$53,MATCH($B5,'Parametri Modello'!$A$50:$A$53,0))*'Parametri Modello'!$B$44))))*(1+IF(IF($B5="D",'Info Lega'!$B$25,IF($B5="C",'Info Lega'!$B$26,"No"))="Si",'Parametri Modello'!$B$5,0))*(1+MAX(-0.25,MIN(0.25,IF(OR($T5="",$I5="",$I5=0,INDEX('Parametri Modello'!$B$19:$B$22,MATCH($B5,'Parametri Modello'!$A$19:$A$22,0))="",INDEX('Parametri Modello'!$B$19:$B$22,MATCH($B5,'Parametri Modello'!$A$19:$A$22,0))=0),0,(($T5-INDEX('Parametri Modello'!$B$19:$B$22,MATCH($B5,'Parametri Modello'!$A$19:$A$22,0)))/INDEX('Parametri Modello'!$B$19:$B$22,MATCH($B5,'Parametri Modello'!$A$19:$A$22,0)))*'Parametri Modello'!$B$9))))*(1+IF('Parametri Modello'!$B$27="Si",MAX(-'Parametri Modello'!$B$28,MIN('Parametri Modello'!$B$28*1.5,IF(OR(INDEX('Parametri Modello'!$F$32:$F$35,MATCH($B5,'Parametri Modello'!$A$32:$A$35,0))="",INDEX('Parametri Modello'!$F$32:$F$35,MATCH($B5,'Parametri Modello'!$A$32:$A$35,0))=0),0,(1/INDEX('Parametri Modello'!$F$32:$F$35,MATCH($B5,'Parametri Modello'!$A$32:$A$35,0))-1)*'Parametri Modello'!$B$28))),0)))*(1-INDEX('Parametri Modello'!$B$12:$B$15,MATCH($B5,'Parametri Modello'!$A$12:$A$15,0)))),0),"") -> 178 | H5: =IFERROR(ROUND((IF($V5<=INDEX('Parametri Modello'!$C$57:$C$60,MATCH($B5,'Parametri Modello'!$A$57:$A$60,0)),IF(INDEX('Parametri Modello'!$E$57:$E$60,MATCH($B5,'Parametri Modello'!$A$57:$A$60,0))=0,0,($O5/INDEX('Parametri Modello'!$E$57:$E$60,MATCH($B5,'Parametri Modello'!$A$57:$A$60,0)))*(INDEX('Parametri Modello'!$D$57:$D$60,MATCH($B5,'Parametri Modello'!$A$57:$A$60,0))*(INDEX('Parametri Modello'!$B$50:$B$53,MATCH($B5,'Parametri Modello'!$A$50:$A$53,0))*'Parametri Modello'!$B$44))),IF(INDEX('Parametri Modello'!$F$57:$F$60,MATCH($B5,'Parametri Modello'!$A$57:$A$60,0))=0,0,($O5/INDEX('Parametri Modello'!$F$57:$F$60,MATCH($B5,'Parametri Modello'!$A$57:$A$60,0)))*((1-INDEX('Parametri Modello'!$D$57:$D$60,MATCH($B5,'Parametri Modello'!$A$57:$A$60,0)))*(INDEX('Parametri Modello'!$B$50:$B$53,MATCH($B5,'Parametri Modello'!$A$50:$A$53,0))*'Parametri Modello'!$B$44))))*(1+IF(IF($B5="D",'Info Lega'!$B$25,IF($B5="C",'Info Lega'!$B$26,"No"))="Si",'Parametri Modello'!$B$5,0))*(1+MAX(-0.25,MIN(0.25,IF(OR($T5="",$I5="",$I5=0,INDEX('Parametri Modello'!$B$19:$B$22,MATCH($B5,'Parametri Modello'!$A$19:$A$22,0))="",INDEX('Parametri Modello'!$B$19:$B$22,MATCH($B5,'Parametri Modello'!$A$19:$A$22,0))=0),0,(($T5-INDEX('Parametri Modello'!$B$19:$B$22,MATCH($B5,'Parametri Modello'!$A$19:$A$22,0)))/INDEX('Parametri Modello'!$B$19:$B$22,MATCH($B5,'Parametri Modello'!$A$19:$A$22,0)))*'Parametri Modello'!$B$9))))*(1+IF('Parametri Modello'!$B$27="Si",MAX(-'Parametri Modello'!$B$28,MIN('Parametri Modello'!$B$28*1.5,IF(OR(INDEX('Parametri Modello'!$F$32:$F$35,MATCH($B5,'Parametri Modello'!$A$32:$A$35,0))="",INDEX('Parametri Modello'!$F$32:$F$35,MATCH($B5,'Parametri Modello'!$A$32:$A$35,0))=0),0,(1/INDEX('Parametri Modello'!$F$32:$F$35,MATCH($B5,'Parametri Modello'!$A$32:$A$35,0))-1)*'Parametri Modello'!$B$28))),0)))*(1+INDEX('Parametri Modello'!$B$12:$B$15,MATCH($B5,'Parametri Modello'!$A$12:$A$15,0))),0),"") -> 330 | I5: =IFERROR(INDEX('Input Statistiche 2025_26'!$F$3:$F$665,MATCH($A5,'Input Statistiche 2025_26'!$A$3:$A$665,0)),"") -> 33 | J5: =IFERROR(IF($I5="","",MAX(0,38-$I5)),"") -> 5 | K5: =IFERROR(INDEX('Input Statistiche 2025_26'!$I$3:$I$665,MATCH($A5,'Input Statistiche 2025_26'!$A$3:$A$665,0)),"") -> 12 | L5: =IFERROR(INDEX('Input Statistiche 2025_26'!$O$3:$O$665,MATCH($A5,'Input Statistiche 2025_26'!$A$3:$A$665,0)),"") -> 5 | N5: =IFERROR(INDEX('Input Giocatori 2026_27'!$E$3:$E$493,MATCH($A5,'Input Giocatori 2026_27'!$A$3:$A$493,0)),"") -> 28 | O5: =IFERROR(INDEX('Input Giocatori 2026_27'!$G$3:$G$493,MATCH($A5,'Input Giocatori 2026_27'!$A$3:$A$493,0)),"") -> 271 | P5: =IFERROR(IF($O5="","",IF((1-(COUNTIFS($B$2:$B$492,$B5,$O$2:$O$492,">"&$O5)+1-1)/COUNTIF($B$2:$B$492,$B5))>=0.85,"Top",IF((1-(COUNTIFS($B$2:$B$492,$B5,$O$2:$O$492,">"&$O5)+1-1)/COUNTIF($B$2:$B$492,$B5))>=0.6,"Buono",IF((1-(COUNTIFS($B$2:$B$492,$B5,$O$2:$O$492,">"&$O5)+1-1)/COUNTIF($B$2:$B$492,$B5))>=0.3,"Nella Media","Scommessa/Riserva")))),"") -> Top | Q5: =IF($D5="",COUNTIF($D$2:$D5,""),"") -> 4 | R5: =IF($D5='Info Lega'!$B$28,COUNTIFS($D$2:$D5,'Info Lega'!$B$28),"") | S5: =IFERROR(INDEX('Input Statistiche 2025_26'!$G$3:$G$665,MATCH($A5,'Input Statistiche 2025_26'!$A$3:$A$665,0)),"") -> 6.21 | T5: =IFERROR(INDEX('Input Statistiche 2025_26'!$H$3:$H$665,MATCH($A5,'Input Statistiche 2025_26'!$A$3:$A$665,0)),"") -> 7.44 | U5: =IF(OR('La Mia Rosa'!$O$12="",$D5<>""),"",IF($F5<='La Mia Rosa'!$O$12*'Parametri Modello'!$B$24,"OK",IF($F5<='La Mia Rosa'!$O$12*'Parametri Modello'!$B$25,"Attenzione","Rischio Alto"))) -> Rischio Alto | V5: =IFERROR(COUNTIFS($B$2:$B$492,$B5,$O$2:$O$492,">"&$O5)+1,"") -> 4 | W5: ='Info Lega'!$B$4-SUMIFS($M$2:$M$492,$D$2:$D$492,'Info Lega'!$B$28) -> 1000 | X5: =('Info Lega'!$B$5-COUNTIFS($D$2:$D$492,'Info Lega'!$B$28,$B$2:$B$492,"P"))+('Info Lega'!$B$6-COUNTIFS($D$2:$D$492,'Info Lega'!$B$28,$B$2:$B$492,"D"))+('Info Lega'!$B$7-COUNTIFS($D$2:$D$492,'Info Lega'!$B$28,$B$2:$B$492,"C"))+('Info Lega'!$B$8-COUNTIFS($D$2:$D$492,'Info Lega'!$B$28,$B$2:$B$492,"A")) -> 25 | Y5: =X5*'Parametri Modello'!$B$30 -> 25 | Z5: =MAX(0,W5-Y5) -> 975 | AA5: =MIN(F5,Z5) -> 284 | AC5: =IF(AB5="","",IF(AB5>AA5,"PASS",IF(AB5<=AA5*0.85,"BID","ATTENZIONE"))) | AD5: =IF(I5="","",ROUND(100*(1-EXP(-I5/30)),0)) -> 67 | AE5: =IFERROR(INDEX('Stato Asta'!$G$9:$G$12,MATCH($B5,'Stato Asta'!$A$9:$A$12,0)),"") -> 🔴 Non aspettare
A6: 254 | B6: D | C6: Dimarco | E6: =IF(COUNTIF('Info Strategia'!$D$2:$D$51,$C6)>0,"SI","NO") -> NO | F6: =IFERROR(ROUND(($G6+($H6-$G6)*'Info Strategia'!$B$6)*(1+IF($E6="SI",'Parametri Modello'!$B$7*'Info Strategia'!$B$6,0)),0),"") -> 190 | G6: =IFERROR(ROUND(MAX(1,(IF($V6<=INDEX('Parametri Modello'!$C$57:$C$60,MATCH($B6,'Parametri Modello'!$A$57:$A$60,0)),IF(INDEX('Parametri Modello'!$E$57:$E$60,MATCH($B6,'Parametri Modello'!$A$57:$A$60,0))=0,0,($O6/INDEX('Parametri Modello'!$E$57:$E$60,MATCH($B6,'Parametri Modello'!$A$57:$A$60,0)))*(INDEX('Parametri Modello'!$D$57:$D$60,MATCH($B6,'Parametri Modello'!$A$57:$A$60,0))*(INDEX('Parametri Modello'!$B$50:$B$53,MATCH($B6,'Parametri Modello'!$A$50:$A$53,0))*'Parametri Modello'!$B$44))),IF(INDEX('Parametri Modello'!$F$57:$F$60,MATCH($B6,'Parametri Modello'!$A$57:$A$60,0))=0,0,($O6/INDEX('Parametri Modello'!$F$57:$F$60,MATCH($B6,'Parametri Modello'!$A$57:$A$60,0)))*((1-INDEX('Parametri Modello'!$D$57:$D$60,MATCH($B6,'Parametri Modello'!$A$57:$A$60,0)))*(INDEX('Parametri Modello'!$B$50:$B$53,MATCH($B6,'Parametri Modello'!$A$50:$A$53,0))*'Parametri Modello'!$B$44))))*(1+IF(IF($B6="D",'Info Lega'!$B$25,IF($B6="C",'Info Lega'!$B$26,"No"))="Si",'Parametri Modello'!$B$5,0))*(1+MAX(-0.25,MIN(0.25,IF(OR($T6="",$I6="",$I6=0,INDEX('Parametri Modello'!$B$19:$B$22,MATCH($B6,'Parametri Modello'!$A$19:$A$22,0))="",INDEX('Parametri Modello'!$B$19:$B$22,MATCH($B6,'Parametri Modello'!$A$19:$A$22,0))=0),0,(($T6-INDEX('Parametri Modello'!$B$19:$B$22,MATCH($B6,'Parametri Modello'!$A$19:$A$22,0)))/INDEX('Parametri Modello'!$B$19:$B$22,MATCH($B6,'Parametri Modello'!$A$19:$A$22,0)))*'Parametri Modello'!$B$9))))*(1+IF('Parametri Modello'!$B$27="Si",MAX(-'Parametri Modello'!$B$28,MIN('Parametri Modello'!$B$28*1.5,IF(OR(INDEX('Parametri Modello'!$F$32:$F$35,MATCH($B6,'Parametri Modello'!$A$32:$A$35,0))="",INDEX('Parametri Modello'!$F$32:$F$35,MATCH($B6,'Parametri Modello'!$A$32:$A$35,0))=0),0,(1/INDEX('Parametri Modello'!$F$32:$F$35,MATCH($B6,'Parametri Modello'!$A$32:$A$35,0))-1)*'Parametri Modello'!$B$28))),0)))*(1-INDEX('Parametri Modello'!$B$12:$B$15,MATCH($B6,'Parametri Modello'!$A$12:$A$15,0)))),0),"") -> 141 | H6: =IFERROR(ROUND((IF($V6<=INDEX('Parametri Modello'!$C$57:$C$60,MATCH($B6,'Parametri Modello'!$A$57:$A$60,0)),IF(INDEX('Parametri Modello'!$E$57:$E$60,MATCH($B6,'Parametri Modello'!$A$57:$A$60,0))=0,0,($O6/INDEX('Parametri Modello'!$E$57:$E$60,MATCH($B6,'Parametri Modello'!$A$57:$A$60,0)))*(INDEX('Parametri Modello'!$D$57:$D$60,MATCH($B6,'Parametri Modello'!$A$57:$A$60,0))*(INDEX('Parametri Modello'!$B$50:$B$53,MATCH($B6,'Parametri Modello'!$A$50:$A$53,0))*'Parametri Modello'!$B$44))),IF(INDEX('Parametri Modello'!$F$57:$F$60,MATCH($B6,'Parametri Modello'!$A$57:$A$60,0))=0,0,($O6/INDEX('Parametri Modello'!$F$57:$F$60,MATCH($B6,'Parametri Modello'!$A$57:$A$60,0)))*((1-INDEX('Parametri Modello'!$D$57:$D$60,MATCH($B6,'Parametri Modello'!$A$57:$A$60,0)))*(INDEX('Parametri Modello'!$B$50:$B$53,MATCH($B6,'Parametri Modello'!$A$50:$A$53,0))*'Parametri Modello'!$B$44))))*(1+IF(IF($B6="D",'Info Lega'!$B$25,IF($B6="C",'Info Lega'!$B$26,"No"))="Si",'Parametri Modello'!$B$5,0))*(1+MAX(-0.25,MIN(0.25,IF(OR($T6="",$I6="",$I6=0,INDEX('Parametri Modello'!$B$19:$B$22,MATCH($B6,'Parametri Modello'!$A$19:$A$22,0))="",INDEX('Parametri Modello'!$B$19:$B$22,MATCH($B6,'Parametri Modello'!$A$19:$A$22,0))=0),0,(($T6-INDEX('Parametri Modello'!$B$19:$B$22,MATCH($B6,'Parametri Modello'!$A$19:$A$22,0)))/INDEX('Parametri Modello'!$B$19:$B$22,MATCH($B6,'Parametri Modello'!$A$19:$A$22,0)))*'Parametri Modello'!$B$9))))*(1+IF('Parametri Modello'!$B$27="Si",MAX(-'Parametri Modello'!$B$28,MIN('Parametri Modello'!$B$28*1.5,IF(OR(INDEX('Parametri Modello'!$F$32:$F$35,MATCH($B6,'Parametri Modello'!$A$32:$A$35,0))="",INDEX('Parametri Modello'!$F$32:$F$35,MATCH($B6,'Parametri Modello'!$A$32:$A$35,0))=0),0,(1/INDEX('Parametri Modello'!$F$32:$F$35,MATCH($B6,'Parametri Modello'!$A$32:$A$35,0))-1)*'Parametri Modello'!$B$28))),0)))*(1+INDEX('Parametri Modello'!$B$12:$B$15,MATCH($B6,'Parametri Modello'!$A$12:$A$15,0))),0),"") -> 211 | I6: =IFERROR(INDEX('Input Statistiche 2025_26'!$F$3:$F$665,MATCH($A6,'Input Statistiche 2025_26'!$A$3:$A$665,0)),"") -> 35 | J6: =IFERROR(IF($I6="","",MAX(0,38-$I6)),"") -> 3 | K6: =IFERROR(INDEX('Input Statistiche 2025_26'!$I$3:$I$665,MATCH($A6,'Input Statistiche 2025_26'!$A$3:$A$665,0)),"") -> 7 | L6: =IFERROR(INDEX('Input Statistiche 2025_26'!$O$3:$O$665,MATCH($A6,'Input Statistiche 2025_26'!$A$3:$A$665,0)),"") -> 17 | N6: =IFERROR(INDEX('Input Giocatori 2026_27'!$E$3:$E$493,MATCH($A6,'Input Giocatori 2026_27'!$A$3:$A$493,0)),"") -> 32 | O6: =IFERROR(INDEX('Input Giocatori 2026_27'!$G$3:$G$493,MATCH($A6,'Input Giocatori 2026_27'!$A$3:$A$493,0)),"") -> 265 | P6: =IFERROR(IF($O6="","",IF((1-(COUNTIFS($B$2:$B$492,$B6,$O$2:$O$492,">"&$O6)+1-1)/COUNTIF($B$2:$B$492,$B6))>=0.85,"Top",IF((1-(COUNTIFS($B$2:$B$492,$B6,$O$2:$O$492,">"&$O6)+1-1)/COUNTIF($B$2:$B$492,$B6))>=0.6,"Buono",IF((1-(COUNTIFS($B$2:$B$492,$B6,$O$2:$O$492,">"&$O6)+1-1)/COUNTIF($B$2:$B$492,$B6))>=0.3,"Nella Media","Scommessa/Riserva")))),"") -> Top | Q6: =IF($D6="",COUNTIF($D$2:$D6,""),"") -> 5 | R6: =IF($D6='Info Lega'!$B$28,COUNTIFS($D$2:$D6,'Info Lega'!$B$28),"") | S6: =IFERROR(INDEX('Input Statistiche 2025_26'!$G$3:$G$665,MATCH($A6,'Input Statistiche 2025_26'!$A$3:$A$665,0)),"") -> 6.6 | T6: =IFERROR(INDEX('Input Statistiche 2025_26'!$H$3:$H$665,MATCH($A6,'Input Statistiche 2025_26'!$A$3:$A$665,0)),"") -> 7.64 | U6: =IF(OR('La Mia Rosa'!$O$12="",$D6<>""),"",IF($F6<='La Mia Rosa'!$O$12*'Parametri Modello'!$B$24,"OK",IF($F6<='La Mia Rosa'!$O$12*'Parametri Modello'!$B$25,"Attenzione","Rischio Alto"))) -> Rischio Alto | V6: =IFERROR(COUNTIFS($B$2:$B$492,$B6,$O$2:$O$492,">"&$O6)+1,"") -> 1 | W6: ='Info Lega'!$B$4-SUMIFS($M$2:$M$492,$D$2:$D$492,'Info Lega'!$B$28) -> 1000 | X6: =('Info Lega'!$B$5-COUNTIFS($D$2:$D$492,'Info Lega'!$B$28,$B$2:$B$492,"P"))+('Info Lega'!$B$6-COUNTIFS($D$2:$D$492,'Info Lega'!$B$28,$B$2:$B$492,"D"))+('Info Lega'!$B$7-COUNTIFS($D$2:$D$492,'Info Lega'!$B$28,$B$2:$B$492,"C"))+('Info Lega'!$B$8-COUNTIFS($D$2:$D$492,'Info Lega'!$B$28,$B$2:$B$492,"A")) -> 25 | Y6: =X6*'Parametri Modello'!$B$30 -> 25 | Z6: =MAX(0,W6-Y6) -> 975 | AA6: =MIN(F6,Z6) -> 190 | AC6: =IF(AB6="","",IF(AB6>AA6,"PASS",IF(AB6<=AA6*0.85,"BID","ATTENZIONE"))) | AD6: =IF(I6="","",ROUND(100*(1-EXP(-I6/30)),0)) -> 69 | AE6: =IFERROR(INDEX('Stato Asta'!$G$9:$G$12,MATCH($B6,'Stato Asta'!$A$9:$A$12,0)),"") -> 🟡 Attesa rischiosa
A7: 6875 | B7: C | C7: Paz N. | E7: =IF(COUNTIF('Info Strategia'!$D$2:$D$51,$C7)>0,"SI","NO") -> NO | F7: =IFERROR(ROUND(($G7+($H7-$G7)*'Info Strategia'!$B$6)*(1+IF($E7="SI",'Parametri Modello'!$B$7*'Info Strategia'!$B$6,0)),0),"") -> 171 | G7: =IFERROR(ROUND(MAX(1,(IF($V7<=INDEX('Parametri Modello'!$C$57:$C$60,MATCH($B7,'Parametri Modello'!$A$57:$A$60,0)),IF(INDEX('Parametri Modello'!$E$57:$E$60,MATCH($B7,'Parametri Modello'!$A$57:$A$60,0))=0,0,($O7/INDEX('Parametri Modello'!$E$57:$E$60,MATCH($B7,'Parametri Modello'!$A$57:$A$60,0)))*(INDEX('Parametri Modello'!$D$57:$D$60,MATCH($B7,'Parametri Modello'!$A$57:$A$60,0))*(INDEX('Parametri Modello'!$B$50:$B$53,MATCH($B7,'Parametri Modello'!$A$50:$A$53,0))*'Parametri Modello'!$B$44))),IF(INDEX('Parametri Modello'!$F$57:$F$60,MATCH($B7,'Parametri Modello'!$A$57:$A$60,0))=0,0,($O7/INDEX('Parametri Modello'!$F$57:$F$60,MATCH($B7,'Parametri Modello'!$A$57:$A$60,0)))*((1-INDEX('Parametri Modello'!$D$57:$D$60,MATCH($B7,'Parametri Modello'!$A$57:$A$60,0)))*(INDEX('Parametri Modello'!$B$50:$B$53,MATCH($B7,'Parametri Modello'!$A$50:$A$53,0))*'Parametri Modello'!$B$44))))*(1+IF(IF($B7="D",'Info Lega'!$B$25,IF($B7="C",'Info Lega'!$B$26,"No"))="Si",'Parametri Modello'!$B$5,0))*(1+MAX(-0.25,MIN(0.25,IF(OR($T7="",$I7="",$I7=0,INDEX('Parametri Modello'!$B$19:$B$22,MATCH($B7,'Parametri Modello'!$A$19:$A$22,0))="",INDEX('Parametri Modello'!$B$19:$B$22,MATCH($B7,'Parametri Modello'!$A$19:$A$22,0))=0),0,(($T7-INDEX('Parametri Modello'!$B$19:$B$22,MATCH($B7,'Parametri Modello'!$A$19:$A$22,0)))/INDEX('Parametri Modello'!$B$19:$B$22,MATCH($B7,'Parametri Modello'!$A$19:$A$22,0)))*'Parametri Modello'!$B$9))))*(1+IF('Parametri Modello'!$B$27="Si",MAX(-'Parametri Modello'!$B$28,MIN('Parametri Modello'!$B$28*1.5,IF(OR(INDEX('Parametri Modello'!$F$32:$F$35,MATCH($B7,'Parametri Modello'!$A$32:$A$35,0))="",INDEX('Parametri Modello'!$F$32:$F$35,MATCH($B7,'Parametri Modello'!$A$32:$A$35,0))=0),0,(1/INDEX('Parametri Modello'!$F$32:$F$35,MATCH($B7,'Parametri Modello'!$A$32:$A$35,0))-1)*'Parametri Modello'!$B$28))),0)))*(1-INDEX('Parametri Modello'!$B$12:$B$15,MATCH($B7,'Parametri Modello'!$A$12:$A$15,0)))),0),"") -> 116 | H7: =IFERROR(ROUND((IF($V7<=INDEX('Parametri Modello'!$C$57:$C$60,MATCH($B7,'Parametri Modello'!$A$57:$A$60,0)),IF(INDEX('Parametri Modello'!$E$57:$E$60,MATCH($B7,'Parametri Modello'!$A$57:$A$60,0))=0,0,($O7/INDEX('Parametri Modello'!$E$57:$E$60,MATCH($B7,'Parametri Modello'!$A$57:$A$60,0)))*(INDEX('Parametri Modello'!$D$57:$D$60,MATCH($B7,'Parametri Modello'!$A$57:$A$60,0))*(INDEX('Parametri Modello'!$B$50:$B$53,MATCH($B7,'Parametri Modello'!$A$50:$A$53,0))*'Parametri Modello'!$B$44))),IF(INDEX('Parametri Modello'!$F$57:$F$60,MATCH($B7,'Parametri Modello'!$A$57:$A$60,0))=0,0,($O7/INDEX('Parametri Modello'!$F$57:$F$60,MATCH($B7,'Parametri Modello'!$A$57:$A$60,0)))*((1-INDEX('Parametri Modello'!$D$57:$D$60,MATCH($B7,'Parametri Modello'!$A$57:$A$60,0)))*(INDEX('Parametri Modello'!$B$50:$B$53,MATCH($B7,'Parametri Modello'!$A$50:$A$53,0))*'Parametri Modello'!$B$44))))*(1+IF(IF($B7="D",'Info Lega'!$B$25,IF($B7="C",'Info Lega'!$B$26,"No"))="Si",'Parametri Modello'!$B$5,0))*(1+MAX(-0.25,MIN(0.25,IF(OR($T7="",$I7="",$I7=0,INDEX('Parametri Modello'!$B$19:$B$22,MATCH($B7,'Parametri Modello'!$A$19:$A$22,0))="",INDEX('Parametri Modello'!$B$19:$B$22,MATCH($B7,'Parametri Modello'!$A$19:$A$22,0))=0),0,(($T7-INDEX('Parametri Modello'!$B$19:$B$22,MATCH($B7,'Parametri Modello'!$A$19:$A$22,0)))/INDEX('Parametri Modello'!$B$19:$B$22,MATCH($B7,'Parametri Modello'!$A$19:$A$22,0)))*'Parametri Modello'!$B$9))))*(1+IF('Parametri Modello'!$B$27="Si",MAX(-'Parametri Modello'!$B$28,MIN('Parametri Modello'!$B$28*1.5,IF(OR(INDEX('Parametri Modello'!$F$32:$F$35,MATCH($B7,'Parametri Modello'!$A$32:$A$35,0))="",INDEX('Parametri Modello'!$F$32:$F$35,MATCH($B7,'Parametri Modello'!$A$32:$A$35,0))=0),0,(1/INDEX('Parametri Modello'!$F$32:$F$35,MATCH($B7,'Parametri Modello'!$A$32:$A$35,0))-1)*'Parametri Modello'!$B$28))),0)))*(1+INDEX('Parametri Modello'!$B$12:$B$15,MATCH($B7,'Parametri Modello'!$A$12:$A$15,0))),0),"") -> 194 | I7: =IFERROR(INDEX('Input Statistiche 2025_26'!$F$3:$F$665,MATCH($A7,'Input Statistiche 2025_26'!$A$3:$A$665,0)),"") -> 35 | J7: =IFERROR(IF($I7="","",MAX(0,38-$I7)),"") -> 3 | K7: =IFERROR(INDEX('Input Statistiche 2025_26'!$I$3:$I$665,MATCH($A7,'Input Statistiche 2025_26'!$A$3:$A$665,0)),"") -> 12 | L7: =IFERROR(INDEX('Input Statistiche 2025_26'!$O$3:$O$665,MATCH($A7,'Input Statistiche 2025_26'!$A$3:$A$665,0)),"") -> 5 | N7: =IFERROR(INDEX('Input Giocatori 2026_27'!$E$3:$E$493,MATCH($A7,'Input Giocatori 2026_27'!$A$3:$A$493,0)),"") -> 30 | O7: =IFERROR(INDEX('Input Giocatori 2026_27'!$G$3:$G$493,MATCH($A7,'Input Giocatori 2026_27'!$A$3:$A$493,0)),"") -> 250 | P7: =IFERROR(IF($O7="","",IF((1-(COUNTIFS($B$2:$B$492,$B7,$O$2:$O$492,">"&$O7)+1-1)/COUNTIF($B$2:$B$492,$B7))>=0.85,"Top",IF((1-(COUNTIFS($B$2:$B$492,$B7,$O$2:$O$492,">"&$O7)+1-1)/COUNTIF($B$2:$B$492,$B7))>=0.6,"Buono",IF((1-(COUNTIFS($B$2:$B$492,$B7,$O$2:$O$492,">"&$O7)+1-1)/COUNTIF($B$2:$B$492,$B7))>=0.3,"Nella Media","Scommessa/Riserva")))),"") -> Top | Q7: =IF($D7="",COUNTIF($D$2:$D7,""),"") -> 6 | R7: =IF($D7='Info Lega'!$B$28,COUNTIFS($D$2:$D7,'Info Lega'!$B$28),"") | S7: =IFERROR(INDEX('Input Statistiche 2025_26'!$G$3:$G$665,MATCH($A7,'Input Statistiche 2025_26'!$A$3:$A$665,0)),"") -> 6.37 | T7: =IFERROR(INDEX('Input Statistiche 2025_26'!$H$3:$H$665,MATCH($A7,'Input Statistiche 2025_26'!$A$3:$A$665,0)),"") -> 7.3 | U7: =IF(OR('La Mia Rosa'!$O$12="",$D7<>""),"",IF($F7<='La Mia Rosa'!$O$12*'Parametri Modello'!$B$24,"OK",IF($F7<='La Mia Rosa'!$O$12*'Parametri Modello'!$B$25,"Attenzione","Rischio Alto"))) -> Rischio Alto | V7: =IFERROR(COUNTIFS($B$2:$B$492,$B7,$O$2:$O$492,">"&$O7)+1,"") -> 1 | W7: ='Info Lega'!$B$4-SUMIFS($M$2:$M$492,$D$2:$D$492,'Info Lega'!$B$28) -> 1000 | X7: =('Info Lega'!$B$5-COUNTIFS($D$2:$D$492,'Info Lega'!$B$28,$B$2:$B$492,"P"))+('Info Lega'!$B$6-COUNTIFS($D$2:$D$492,'Info Lega'!$B$28,$B$2:$B$492,"D"))+('Info Lega'!$B$7-COUNTIFS($D$2:$D$492,'Info Lega'!$B$28,$B$2:$B$492,"C"))+('Info Lega'!$B$8-COUNTIFS($D$2:$D$492,'Info Lega'!$B$28,$B$2:$B$492,"A")) -> 25 | Y7: =X7*'Parametri Modello'!$B$30 -> 25 | Z7: =MAX(0,W7-Y7) -> 975 | AA7: =MIN(F7,Z7) -> 171 | AC7: =IF(AB7="","",IF(AB7>AA7,"PASS",IF(AB7<=AA7*0.85,"BID","ATTENZIONE"))) | AD7: =IF(I7="","",ROUND(100*(1-EXP(-I7/30)),0)) -> 69 | AE7: =IFERROR(INDEX('Stato Asta'!$G$9:$G$12,MATCH($B7,'Stato Asta'!$A$9:$A$12,0)),"") -> 🟡 Attesa rischiosa
A8: 4777 | B8: C | C8: McTominay | E8: =IF(COUNTIF('Info Strategia'!$D$2:$D$51,$C8)>0,"SI","NO") -> NO | F8: =IFERROR(ROUND(($G8+($H8-$G8)*'Info Strategia'!$B$6)*(1+IF($E8="SI",'Parametri Modello'!$B$7*'Info Strategia'!$B$6,0)),0),"") -> 164 | G8: =IFERROR(ROUND(MAX(1,(IF($V8<=INDEX('Parametri Modello'!$C$57:$C$60,MATCH($B8,'Parametri Modello'!$A$57:$A$60,0)),IF(INDEX('Parametri Modello'!$E$57:$E$60,MATCH($B8,'Parametri Modello'!$A$57:$A$60,0))=0,0,($O8/INDEX('Parametri Modello'!$E$57:$E$60,MATCH($B8,'Parametri Modello'!$A$57:$A$60,0)))*(INDEX('Parametri Modello'!$D$57:$D$60,MATCH($B8,'Parametri Modello'!$A$57:$A$60,0))*(INDEX('Parametri Modello'!$B$50:$B$53,MATCH($B8,'Parametri Modello'!$A$50:$A$53,0))*'Parametri Modello'!$B$44))),IF(INDEX('Parametri Modello'!$F$57:$F$60,MATCH($B8,'Parametri Modello'!$A$57:$A$60,0))=0,0,($O8/INDEX('Parametri Modello'!$F$57:$F$60,MATCH($B8,'Parametri Modello'!$A$57:$A$60,0)))*((1-INDEX('Parametri Modello'!$D$57:$D$60,MATCH($B8,'Parametri Modello'!$A$57:$A$60,0)))*(INDEX('Parametri Modello'!$B$50:$B$53,MATCH($B8,'Parametri Modello'!$A$50:$A$53,0))*'Parametri Modello'!$B$44))))*(1+IF(IF($B8="D",'Info Lega'!$B$25,IF($B8="C",'Info Lega'!$B$26,"No"))="Si",'Parametri Modello'!$B$5,0))*(1+MAX(-0.25,MIN(0.25,IF(OR($T8="",$I8="",$I8=0,INDEX('Parametri Modello'!$B$19:$B$22,MATCH($B8,'Parametri Modello'!$A$19:$A$22,0))="",INDEX('Parametri Modello'!$B$19:$B$22,MATCH($B8,'Parametri Modello'!$A$19:$A$22,0))=0),0,(($T8-INDEX('Parametri Modello'!$B$19:$B$22,MATCH($B8,'Parametri Modello'!$A$19:$A$22,0)))/INDEX('Parametri Modello'!$B$19:$B$22,MATCH($B8,'Parametri Modello'!$A$19:$A$22,0)))*'Parametri Modello'!$B$9))))*(1+IF('Parametri Modello'!$B$27="Si",MAX(-'Parametri Modello'!$B$28,MIN('Parametri Modello'!$B$28*1.5,IF(OR(INDEX('Parametri Modello'!$F$32:$F$35,MATCH($B8,'Parametri Modello'!$A$32:$A$35,0))="",INDEX('Parametri Modello'!$F$32:$F$35,MATCH($B8,'Parametri Modello'!$A$32:$A$35,0))=0),0,(1/INDEX('Parametri Modello'!$F$32:$F$35,MATCH($B8,'Parametri Modello'!$A$32:$A$35,0))-1)*'Parametri Modello'!$B$28))),0)))*(1-INDEX('Parametri Modello'!$B$12:$B$15,MATCH($B8,'Parametri Modello'!$A$12:$A$15,0)))),0),"") -> 112 | H8: =IFERROR(ROUND((IF($V8<=INDEX('Parametri Modello'!$C$57:$C$60,MATCH($B8,'Parametri Modello'!$A$57:$A$60,0)),IF(INDEX('Parametri Modello'!$E$57:$E$60,MATCH($B8,'Parametri Modello'!$A$57:$A$60,0))=0,0,($O8/INDEX('Parametri Modello'!$E$57:$E$60,MATCH($B8,'Parametri Modello'!$A$57:$A$60,0)))*(INDEX('Parametri Modello'!$D$57:$D$60,MATCH($B8,'Parametri Modello'!$A$57:$A$60,0))*(INDEX('Parametri Modello'!$B$50:$B$53,MATCH($B8,'Parametri Modello'!$A$50:$A$53,0))*'Parametri Modello'!$B$44))),IF(INDEX('Parametri Modello'!$F$57:$F$60,MATCH($B8,'Parametri Modello'!$A$57:$A$60,0))=0,0,($O8/INDEX('Parametri Modello'!$F$57:$F$60,MATCH($B8,'Parametri Modello'!$A$57:$A$60,0)))*((1-INDEX('Parametri Modello'!$D$57:$D$60,MATCH($B8,'Parametri Modello'!$A$57:$A$60,0)))*(INDEX('Parametri Modello'!$B$50:$B$53,MATCH($B8,'Parametri Modello'!$A$50:$A$53,0))*'Parametri Modello'!$B$44))))*(1+IF(IF($B8="D",'Info Lega'!$B$25,IF($B8="C",'Info Lega'!$B$26,"No"))="Si",'Parametri Modello'!$B$5,0))*(1+MAX(-0.25,MIN(0.25,IF(OR($T8="",$I8="",$I8=0,INDEX('Parametri Modello'!$B$19:$B$22,MATCH($B8,'Parametri Modello'!$A$19:$A$22,0))="",INDEX('Parametri Modello'!$B$19:$B$22,MATCH($B8,'Parametri Modello'!$A$19:$A$22,0))=0),0,(($T8-INDEX('Parametri Modello'!$B$19:$B$22,MATCH($B8,'Parametri Modello'!$A$19:$A$22,0)))/INDEX('Parametri Modello'!$B$19:$B$22,MATCH($B8,'Parametri Modello'!$A$19:$A$22,0)))*'Parametri Modello'!$B$9))))*(1+IF('Parametri Modello'!$B$27="Si",MAX(-'Parametri Modello'!$B$28,MIN('Parametri Modello'!$B$28*1.5,IF(OR(INDEX('Parametri Modello'!$F$32:$F$35,MATCH($B8,'Parametri Modello'!$A$32:$A$35,0))="",INDEX('Parametri Modello'!$F$32:$F$35,MATCH($B8,'Parametri Modello'!$A$32:$A$35,0))=0),0,(1/INDEX('Parametri Modello'!$F$32:$F$35,MATCH($B8,'Parametri Modello'!$A$32:$A$35,0))-1)*'Parametri Modello'!$B$28))),0)))*(1+INDEX('Parametri Modello'!$B$12:$B$15,MATCH($B8,'Parametri Modello'!$A$12:$A$15,0))),0),"") -> 186 | I8: =IFERROR(INDEX('Input Statistiche 2025_26'!$F$3:$F$665,MATCH($A8,'Input Statistiche 2025_26'!$A$3:$A$665,0)),"") -> 33 | J8: =IFERROR(IF($I8="","",MAX(0,38-$I8)),"") -> 5 | K8: =IFERROR(INDEX('Input Statistiche 2025_26'!$I$3:$I$665,MATCH($A8,'Input Statistiche 2025_26'!$A$3:$A$665,0)),"") -> 10 | L8: =IFERROR(INDEX('Input Statistiche 2025_26'!$O$3:$O$665,MATCH($A8,'Input Statistiche 2025_26'!$A$3:$A$665,0)),"") -> 2 | N8: =IFERROR(INDEX('Input Giocatori 2026_27'!$E$3:$E$493,MATCH($A8,'Input Giocatori 2026_27'!$A$3:$A$493,0)),"") -> 28 | O8: =IFERROR(INDEX('Input Giocatori 2026_27'!$G$3:$G$493,MATCH($A8,'Input Giocatori 2026_27'!$A$3:$A$493,0)),"") -> 240 | P8: =IFERROR(IF($O8="","",IF((1-(COUNTIFS($B$2:$B$492,$B8,$O$2:$O$492,">"&$O8)+1-1)/COUNTIF($B$2:$B$492,$B8))>=0.85,"Top",IF((1-(COUNTIFS($B$2:$B$492,$B8,$O$2:$O$492,">"&$O8)+1-1)/COUNTIF($B$2:$B$492,$B8))>=0.6,"Buono",IF((1-(COUNTIFS($B$2:$B$492,$B8,$O$2:$O$492,">"&$O8)+1-1)/COUNTIF($B$2:$B$492,$B8))>=0.3,"Nella Media","Scommessa/Riserva")))),"") -> Top | Q8: =IF($D8="",COUNTIF($D$2:$D8,""),"") -> 7 | R8: =IF($D8='Info Lega'!$B$28,COUNTIFS($D$2:$D8,'Info Lega'!$B$28),"") | S8: =IFERROR(INDEX('Input Statistiche 2025_26'!$G$3:$G$665,MATCH($A8,'Input Statistiche 2025_26'!$A$3:$A$665,0)),"") -> 6.39 | T8: =IFERROR(INDEX('Input Statistiche 2025_26'!$H$3:$H$665,MATCH($A8,'Input Statistiche 2025_26'!$A$3:$A$665,0)),"") -> 7.26 | U8: =IF(OR('La Mia Rosa'!$O$12="",$D8<>""),"",IF($F8<='La Mia Rosa'!$O$12*'Parametri Modello'!$B$24,"OK",IF($F8<='La Mia Rosa'!$O$12*'Parametri Modello'!$B$25,"Attenzione","Rischio Alto"))) -> Rischio Alto | V8: =IFERROR(COUNTIFS($B$2:$B$492,$B8,$O$2:$O$492,">"&$O8)+1,"") -> 2 | W8: ='Info Lega'!$B$4-SUMIFS($M$2:$M$492,$D$2:$D$492,'Info Lega'!$B$28) -> 1000 | X8: =('Info Lega'!$B$5-COUNTIFS($D$2:$D$492,'Info Lega'!$B$28,$B$2:$B$492,"P"))+('Info Lega'!$B$6-COUNTIFS($D$2:$D$492,'Info Lega'!$B$28,$B$2:$B$492,"D"))+('Info Lega'!$B$7-COUNTIFS($D$2:$D$492,'Info Lega'!$B$28,$B$2:$B$492,"C"))+('Info Lega'!$B$8-COUNTIFS($D$2:$D$492,'Info Lega'!$B$28,$B$2:$B$492,"A")) -> 25 | Y8: =X8*'Parametri Modello'!$B$30 -> 25 | Z8: =MAX(0,W8-Y8) -> 975 | AA8: =MIN(F8,Z8) -> 164 | AC8: =IF(AB8="","",IF(AB8>AA8,"PASS",IF(AB8<=AA8*0.85,"BID","ATTENZIONE"))) | AD8: =IF(I8="","",ROUND(100*(1-EXP(-I8/30)),0)) -> 67 | AE8: =IFERROR(INDEX('Stato Asta'!$G$9:$G$12,MATCH($B8,'Stato Asta'!$A$9:$A$12,0)),"") -> 🟡 Attesa rischiosa
