Workbook

Sheet Guida
A1: Guida — Motore Prezzi Asta Fantacalcio
A2: Questo file calcola automaticamente un prezzo massimo consigliato e un range di valutazione per ciascun giocatore, in base al budget, alla rosa, alle regole della lega e ai dati FVM/statistici. Il motore si aggiorna modificando i parametri e gli assegnamenti dell'asta.
A3: Come e' organizzato il file
A5: • Info Lega: dati della tua lega (budget, rosa, regole, nomi squadre). 'La Mia Squadra' (B28) identifica la tua squadra.
A6: • Info Strategia: modulo preferito, aggressivita' e lista 'Giocatori Preferiti' (colonna D).
A7: • Parametri Modello: tutte le leve del motore prezzi, incluse soglia minima di presenze storiche e gestione della scarsita'.
A8: • Input Giocatori 2026_27: il listone originale, invariato — e' la fonte dati.
A9: • Output Utente: tabella madre con un giocatore per riga, prezzo consigliato, range, statistiche e stato dell'asta.
A10: • Giocatori Liberi: elenco ordinato dei giocatori non ancora assegnati; il calcolo della scarsita' puo' escludere i giocatori con Qt.A=1.
A11: • La Mia Rosa: la tua rosa attuale + budget speso/rimanente + slot per ruolo, live durante l'asta.
A12: Come si calcola il prezzo (Output Utente)
A14: 1. Prezzo Base FVM = (FVM del giocatore / Somma FVM Pool Totale) × Budget Totale Lega. Il pool comprende, per ciascun ruolo, i migliori N giocatori per FVM, dove N e' il numero totale di slot di quel ruolo nella lega. Il denominatore e' la somma dei pool di tutti i ruoli.
... A58: Generato: 2026-08-12

Sheet Dashboard Asta
A1: DASHBOARD ASTA — vista live
A3: Giocatori chiamati / Totale | D3: % Asta completata | G3: Prezzo medio pagato | I3: Budget medio residuo squadre attive
A4: ='Stato Asta'!$C$3 -> 0 / 491 | D4: ='Stato Asta'!$C$4 -> 0 | G4: ='Stato Asta'!$C$6 | I4: ='Stato Asta'!$C$5 -> 1000
A6: Ruolo | B6: TOP | C6: BUONI | D6: MEDIA | E6: SCOMMESSE | F6: Totale Disp. | G6: Slot Residui Lega | H6: Quality Coverage | I6: Pressione Asta (scarsita') | J6: Pressione Competitiva | K6: Titolari Residui | L6: Riserve Residue | M6: Squadre Candidate Reali
A7: P | B7: ='Stato Asta'!$B$9 -> 7 | C7: ='Stato Asta'!$C$9 -> 11 | D7: ='Stato Asta'!$I$9 -> 6 | E7: ='Stato Asta'!$J$9 -> 0 | F7: ='Stato Asta'!$K$9 -> 24 | G7: ='Stato Asta'!$E$9 -> 24 | H7: ='Stato Asta'!$L$9 -> 0.75 | I7: ='Stato Asta'!$G$9 -> 🟢 Puoi aspettare | J7: ='Pressione Competitiva'!$F$3 -> 🔴 Molto Alta | K7: ='Stato Asta'!$M$9 -> 8 | L7: ='Stato Asta'!$N$9 -> 16 | M7: ='Pressione Competitiva'!$H$3 -> 7
A8: D | B8: ='Stato Asta'!$B$10 -> 18 | C8: ='Stato Asta'!$C$10 -> 37 | D8: ='Stato Asta'!$I$10 -> 56 | E8: ='Stato Asta'!$J$10 -> 37 | F8: ='Stato Asta'!$K$10 -> 148 | G8: ='Stato Asta'!$E$10 -> 64 | H8: ='Stato Asta'!$L$10 -> 0.37162162 | I8: ='Stato Asta'!$G$10 -> 🟢 Puoi aspettare | J8: ='Pressione Competitiva'!$F$4 -> 🔴 Molto Alta | K8: ='Stato Asta'!$M$10 -> 24 | L8: ='Stato Asta'!$N$10 -> 40 | M8: ='Pressione Competitiva'!$H$4 -> 7
A9: C | B9: ='Stato Asta'!$B$11 -> 18 | C9: ='Stato Asta'!$C$11 -> 37 | D9: ='Stato Asta'!$I$11 -> 49 | E9: ='Stato Asta'!$J$11 -> 51 | F9: ='Stato Asta'!$K$11 -> 155 | G9: ='Stato Asta'!$E$11 -> 64 | H9: ='Stato Asta'!$L$11 -> 0.35483871 | I9: ='Stato Asta'!$G$11 -> 🟡 Attesa rischiosa | J9: ='Pressione Competitiva'!$F$5 -> 🔴 Molto Alta | K9: ='Stato Asta'!$M$11 -> 32 | L9: ='Stato Asta'!$N$11 -> 32 | M9: ='Pressione Competitiva'!$H$5 -> 7
A10: A | B10: ='Stato Asta'!$B$12 -> 9 | C10: ='Stato Asta'!$C$12 -> 17 | D10: ='Stato Asta'!$I$12 -> 28 | E10: ='Stato Asta'!$J$12 -> 23 | F10: ='Stato Asta'!$K$12 -> 77 | G10: ='Stato Asta'!$E$12 -> 48 | H10: ='Stato Asta'!$L$12 -> 0.33766234 | I10: ='Stato Asta'!$G$12 -> 🟡 Attesa rischiosa | J10: ='Pressione Competitiva'!$F$6 -> 🔴 Molto Alta | K10: ='Stato Asta'!$M$12 -> 24 | L10: ='Stato Asta'!$N$12 -> 24 | M10: ='Pressione Competitiva'!$H$6 -> 7
A12: LA MIA ROSA — sintesi
A13: Budget Residuo | C13: Slot Residui | E13: FVM Totale Acquistato | G13: Crediti Spesi | I13: Efficienza (FVM/credito)
A14: ='La Mia Rosa'!$S$2 -> 1000 | C14: ='La Mia Rosa'!$S$3 -> 25 | E14: ='La Mia Rosa'!$R$6 -> 0 | G14: ='La Mia Rosa'!$R$7 -> 0 | I14: ='La Mia Rosa'!$R$8
A16: Copertura Titolari (prossimo bisogno)
A17: Ruolo | B17: Titolari Coperti | C17: Titolari Necessari | D17: Riserve Coperte | E17: Prossimo Slot
A18: P | B18: ='La Mia Rosa'!$R$13 -> 0 | C18: ='La Mia Rosa'!$S$13 -> 1 | D18: ='La Mia Rosa'!$T$13 -> 0 | E18: ='La Mia Rosa'!$U$13 -> Titolare
A19: D | B19: ='La Mia Rosa'!$R$14 -> 0 | C19: ='La Mia Rosa'!$S$14 -> 3 | D19: ='La Mia Rosa'!$T$14 -> 0 | E19: ='La Mia Rosa'!$U$14 -> Titolare
A20: C | B20: ='La Mia Rosa'!$R$15 -> 0 | C20: ='La Mia Rosa'!$S$15 -> 4 | D20: ='La Mia Rosa'!$T$15 -> 0 | E20: ='La Mia Rosa'!$U$15 -> Titolare
A21: A | B21: ='La Mia Rosa'!$R$16 -> 0 | C21: ='La Mia Rosa'!$S$16 -> 3 | D21: ='La Mia Rosa'!$T$16 -> 0 | E21: ='La Mia Rosa'!$U$16 -> Titolare

Sheet Decisione Live
A1: DECISIONE LIVE — scheda giocatore in asta
A3: Nome Giocatore (scrivi il nome esatto)
A4: Prezzo Attuale in Asta (crediti)
A6: Ruolo | B6: =IFERROR(INDEX('Output Utente'!$B$2:$B$492,MATCH($B$3,'Output Utente'!$C$2:$C$492,0)),"")
A7: FVM / 1000 | B7: =IFERROR(INDEX('Output Utente'!$O$2:$O$492,MATCH($B$3,'Output Utente'!$C$2:$C$492,0)),"")
A8: Fascia (mercato) | B8: =IFERROR(INDEX('Output Utente'!$P$2:$P$492,MATCH($B$3,'Output Utente'!$C$2:$C$492,0)),"")
A9: Titolare/Riserva (mercato) | B9: =IFERROR(INDEX('Output Utente'!$AF$2:$AF$492,MATCH($B$3,'Output Utente'!$C$2:$C$492,0)),"")
A10: E' un tuo Preferito (Whichlist) | B10: =IFERROR(INDEX('Output Utente'!$E$2:$E$492,MATCH($B$3,'Output Utente'!$C$2:$C$492,0)),"")
A12: VALORE / RANGE / MAX BID
A13: Valutazione Min (Range Min) | B13: =IFERROR(INDEX('Output Utente'!$G$2:$G$492,MATCH($B$3,'Output Utente'!$C$2:$C$492,0)),"") | C13: Prezzo ragionevole minimo secondo il motore.
A14: Valutazione Max (Range Max) | B14: =IFERROR(INDEX('Output Utente'!$H$2:$H$492,MATCH($B$3,'Output Utente'!$C$2:$C$492,0)),"") | C14: Prezzo ragionevole massimo secondo il motore.
A15: Offerta Max Strategica | B15: =IFERROR(INDEX('Output Utente'!$F$2:$F$492,MATCH($B$3,'Output Utente'!$C$2:$C$492,0)),"") | C15: Range + Aggressivita' + eventuale boost Preferito. Non ancora limitata dal budget.
A16: Budget Residuo (tuo) | B16: =IFERROR(INDEX('Output Utente'!$W$2:$W$492,MATCH($B$3,'Output Utente'!$C$2:$C$492,0)),"")
A17: Slot Residui (tuoi, tutti i ruoli) | B17: =IFERROR(INDEX('Output Utente'!$X$2:$X$492,MATCH($B$3,'Output Utente'!$C$2:$C$492,0)),"")
A18: OFFERTA MAX DINAMICA (il tuo vero tetto) | B18: =IFERROR(INDEX('Output Utente'!$AA$2:$AA$492,MATCH($B$3,'Output Utente'!$C$2:$C$492,0)),"") | C18: MIN(Offerta Max Strategica, Budget Spendibile). Non puo' mai superare quanto puoi davvero permetterti.
A20: PRESSIONE COMPETITIVA (informativa)
A21: Pressione Competitiva sul ruolo | B21: =IFERROR(INDEX('Pressione Competitiva'!$F$3:$F$6,MATCH($B$6,'Pressione Competitiva'!$B$3:$B$6,0)),"")
A22: Motivo | B22: =IFERROR(INDEX('Pressione Competitiva'!$G$3:$G$6,MATCH($B$6,'Pressione Competitiva'!$B$3:$B$6,0)),"")
A24: DECISIONE
A25: Prezzo Attuale (da cella B4) | B25: =$B$4 -> 0
A26: Opportunity Gap (Max Bid Dinamica - Prezzo Attuale) | B26: =IF($B$4="","",$B$18-$B$4)
A27: Segnale | B27: =IFERROR(IF($B$4="","",IF($B$26>=$B$18*'Parametri Modello'!$B$68,"🟢 Opportunita'",IF($B$26<=$B$18*'Parametri Modello'!$B$69,"🔴 Sovrapprezzo","🟡 Prezzo Corretto"))),"")
A28: DECISIONE | B28: =IF($B$4="","",IF($B$4>$B$18,"🔴 PASS",IF($B$4<=$B$18*(1-'Parametri Modello'!$B$68),"🟢 BID","🟡 ATTENZIONE")))
A29: Motivo | B29: =IF($B$4="","",IF($B$4>$B$18,"Hai superato il tuo tetto di "&($B$4-$B$18)&" crediti.",IF($B$4<=$B$18*(1-'Parametri Modello'!$B$68),"Margine ampio: "&$B$26&" crediti sotto il tuo tetto.","Margine ridotto: solo "&$B$26&" crediti sotto il tuo tetto.")))
A31: Attenzione | B31: ="Sovrapprezzo rispetto al FVM non significa automaticamente non comprarlo: se la Pressione Competitiva e' alta e ti serve ancora un titolare "&IF($B$6<>"",$B$6,"in questo ruolo")&", puo' comunque valere il tuo Max Bid Dinamico." -> Sovrapprezzo rispetto al FVM non significa automaticamente non comprarlo: se la Pressione Competitiva e' alta e ti serve ancora un titolare in questo ruolo, puo' comunque valere il tuo Max Bid Dinamico.

Sheet Output Utente
A1: Id | B1: R | C1: Nome | D1: Squadra Assegnata | E1: Whichlist | F1: Offerta Max | G1: Valutazione Min | H1: Valutazione Max | I1: Presenze 25/26 (Pv) | J1: Assenze 25/26 (stim.) | K1: Gol 25/26 | L1: Assist 25/26 | M1: Prezzo Pagato | N1: Qt.A | O1: FVM/1000 | P1: Fascia Aspettativa | Q1: _OrdineLiberi | R1: _OrdineMiaRosa | S1: Mv 25/26 | T1: Fm 25/26 | U1: Sostenibilità Budget | V1: Rank FVM nel Ruolo | W1: Budget Residuo | X1: Slot Residui | Y1: Budget Minimo Riserva | Z1: Budget Spendibile | AA1: Offerta Max Dinamica | AB1: Prezzo Corrente | AC1: Decisione Live | AD1: Confidence Storico | AE1: Pressione Ruolo | AF1: Titolare/Riserva (mercato) | AG1: Pressione Competitiva Ruolo | AH1: Opportunity Gap | AI1: Opportunity Gap Segnale | AJ1: Motivo Decisione | AK1: _RankDisponibiliRuoloFascia | AL1: _ChiaveRuoloFasciaRank
A2: 2764 | B2: A | C2: Martinez L. | E2: =IF(COUNTIF('Info Strategia'!$D$2:$D$51,$C2)>0,"SI","NO") -> NO | F2: =IFERROR(ROUND(($G2+($H2-$G2)*'Info Strategia'!$B$6)*(1+IF($E2="SI",'Parametri Modello'!$B$7*'Info Strategia'!$B$6,0)),0),"") -> 397 | G2: =IFERROR(ROUND(MAX(1,(IF($V2<=INDEX('Parametri Modello'!$C$57:$C$60,MATCH($B2,'Parametri Modello'!$A$57:$A$60,0)),IF(INDEX('Parametri Modello'!$E$57:$E$60,MATCH($B2,'Parametri Modello'!$A$57:$A$60,0))=0,0,($O2/INDEX('Parametri Modello'!$E$57:$E$60,MATCH($B2,'Parametri Modello'!$A$57:$A$60,0)))*(INDEX('Parametri Modello'!$D$57:$D$60,MATCH($B2,'Parametri Modello'!$A$57:$A$60,0))*(INDEX('Parametri Modello'!$B$50:$B$53,MATCH($B2,'Parametri Modello'!$A$50:$A$53,0))*'Parametri Modello'!$B$44))),IF(INDEX('Parametri Modello'!$F$57:$F$60,MATCH($B2,'Parametri Modello'!$A$57:$A$60,0))=0,0,($O2/INDEX('Parametri Modello'!$F$57:$F$60,MATCH($B2,'Parametri Modello'!$A$57:$A$60,0)))*((1-INDEX('Parametri Modello'!$D$57:$D$60,MATCH($B2,'Parametri Modello'!$A$57:$A$60,0)))*(INDEX('Parametri Modello'!$B$50:$B$53,MATCH($B2,'Parametri Modello'!$A$50:$A$53,0))*'Parametri Modello'!$B$44))))*(1+IF(IF($B2="D",'Info Lega'!$B$25,IF($B2="C",'Info Lega'!$B$26,"No"))="Si",'Parametri Modello'!$B$5,0))*(1+MAX(-0.25,MIN(0.25,IF(OR($T2="",$I2="",$I2=0,INDEX('Parametri Modello'!$B$19:$B$22,MATCH($B2,'Parametri Modello'!$A$19:$A$22,0))="",INDEX('Parametri Modello'!$B$19:$B$22,MATCH($B2,'Parametri Modello'!$A$19:$A$22,0))=0),0,(($T2-INDEX('Parametri Modello'!$B$19:$B$22,MATCH($B2,'Parametri Modello'!$A$19:$A$22,0)))/INDEX('Parametri Modello'!$B$19:$B$22,MATCH($B2,'Parametri Modello'!$A$19:$A$22,0)))*'Parametri Modello'!$B$9))))*(1+IF('Parametri Modello'!$B$27="Si",MAX(-'Parametri Modello'!$B$28,MIN('Parametri Modello'!$B$28*1.5,IF(OR(INDEX('Parametri Modello'!$F$32:$F$35,MATCH($B2,'Parametri Modello'!$A$32:$A$35,0))="",INDEX('Parametri Modello'!$F$32:$F$35,MATCH($B2,'Parametri Modello'!$A$32:$A$35,0))=0),0,(1/INDEX('Parametri Modello'!$F$32:$F$35,MATCH($B2,'Parametri Modello'!$A$32:$A$35,0))-1)*'Parametri Modello'!$B$28))),0)))*(1-INDEX('Parametri Modello'!$B$12:$B$15,MATCH($B2,'Parametri Modello'!$A$12:$A$15,0)))),0),"") -> 248 | H2: =IFERROR(ROUND((IF($V2<=INDEX('Parametri Modello'!$C$57:$C$60,MATCH($B2,'Parametri Modello'!$A$57:$A$60,0)),IF(INDEX('Parametri Modello'!$E$57:$E$60,MATCH($B2,'Parametri Modello'!$A$57:$A$60,0))=0,0,($O2/INDEX('Parametri Modello'!$E$57:$E$60,MATCH($B2,'Parametri Modello'!$A$57:$A$60,0)))*(INDEX('Parametri Modello'!$D$57:$D$60,MATCH($B2,'Parametri Modello'!$A$57:$A$60,0))*(INDEX('Parametri Modello'!$B$50:$B$53,MATCH($B2,'Parametri Modello'!$A$50:$A$53,0))*'Parametri Modello'!$B$44))),IF(INDEX('Parametri Modello'!$F$57:$F$60,MATCH($B2,'Parametri Modello'!$A$57:$A$60,0))=0,0,($O2/INDEX('Parametri Modello'!$F$57:$F$60,MATCH($B2,'Parametri Modello'!$A$57:$A$60,0)))*((1-INDEX('Parametri Modello'!$D$57:$D$60,MATCH($B2,'Parametri Modello'!$A$57:$A$60,0)))*(INDEX('Parametri Modello'!$B$50:$B$53,MATCH($B2,'Parametri Modello'!$A$50:$A$53,0))*'Parametri Modello'!$B$44))))*(1+IF(IF($B2="D",'Info Lega'!$B$25,IF($B2="C",'Info Lega'!$B$26,"No"))="Si",'Parametri Modello'!$B$5,0))*(1+MAX(-0.25,MIN(0.25,IF(OR($T2="",$I2="",$I2=0,INDEX('Parametri Modello'!$B$19:$B$22,MATCH($B2,'Parametri Modello'!$A$19:$A$22,0))="",INDEX('Parametri Modello'!$B$19:$B$22,MATCH($B2,'Parametri Modello'!$A$19:$A$22,0))=0),0,(($T2-INDEX('Parametri Modello'!$B$19:$B$22,MATCH($B2,'Parametri Modello'!$A$19:$A$22,0)))/INDEX('Parametri Modello'!$B$19:$B$22,MATCH($B2,'Parametri Modello'!$A$19:$A$22,0)))*'Parametri Modello'!$B$9))))*(1+IF('Parametri Modello'!$B$27="Si",MAX(-'Parametri Modello'!$B$28,MIN('Parametri Modello'!$B$28*1.5,IF(OR(INDEX('Parametri Modello'!$F$32:$F$35,MATCH($B2,'Parametri Modello'!$A$32:$A$35,0))="",INDEX('Parametri Modello'!$F$32:$F$35,MATCH($B2,'Parametri Modello'!$A$32:$A$35,0))=0),0,(1/INDEX('Parametri Modello'!$F$32:$F$35,MATCH($B2,'Parametri Modello'!$A$32:$A$35,0))-1)*'Parametri Modello'!$B$28))),0)))*(1+INDEX('Parametri Modello'!$B$12:$B$15,MATCH($B2,'Parametri Modello'!$A$12:$A$15,0))),0),"") -> 461 | I2: =IFERROR(INDEX('Input Statistiche 2025_26'!$F$3:$F$665,MATCH($A2,'Input Statistiche 2025_26'!$A$3:$A$665,0)),"") -> 30 | J2: =IFERROR(IF($I2="","",MAX(0,38-$I2)),"") -> 8 | K2: =IFERROR(INDEX('Input Statistiche 2025_26'!$I$3:$I$665,MATCH($A2,'Input Statistiche 2025_26'!$A$3:$A$665,0)),"") -> 17 | L2: =IFERROR(INDEX('Input Statistiche 2025_26'!$O$3:$O$665,MATCH($A2,'Input Statistiche 2025_26'!$A$3:$A$665,0)),"") -> 6 | N2: =IFERROR(INDEX('Input Giocatori 2026_27'!$E$3:$E$493,MATCH($A2,'Input Giocatori 2026_27'!$A$3:$A$493,0)),"") -> 35 | O2: =IFERROR(INDEX('Input Giocatori 2026_27'!$G$3:$G$493,MATCH($A2,'Input Giocatori 2026_27'!$A$3:$A$493,0)),"") -> 370 | P2: =IFERROR(IF($O2="","",IF((1-(COUNTIFS($B$2:$B$492,$B2,$O$2:$O$492,">"&$O2)+1-1)/COUNTIF($B$2:$B$492,$B2))>='Parametri Modello'!$B$63,"Top",IF((1-(COUNTIFS($B$2:$B$492,$B2,$O$2:$O$492,">"&$O2)+1-1)/COUNTIF($B$2:$B$492,$B2))>='Parametri Modello'!$B$64,"Buono",IF((1-(COUNTIFS($B$2:$B$492,$B2,$O$2:$O$492,">"&$O2)+1-1)/COUNTIF($B$2:$B$492,$B2))>='Parametri Modello'!$B$65,"Nella Media","Scommessa/Riserva")))),"") -> Top | Q2: =IF(AND($D2="",$N2>1),SUMPRODUCT(($D$2:$D2="")*($N$2:$N2>1)),"") -> 1 | R2: =IF($D2='Info Lega'!$B$28,COUNTIFS($D$2:$D2,'Info Lega'!$B$28),"") | S2: =IFERROR(INDEX('Input Statistiche 2025_26'!$G$3:$G$665,MATCH($A2,'Input Statistiche 2025_26'!$A$3:$A$665,0)),"") -> 6.42 | T2: =IFERROR(INDEX('Input Statistiche 2025_26'!$H$3:$H$665,MATCH($A2,'Input Statistiche 2025_26'!$A$3:$A$665,0)),"") -> 8.25 | U2: =IF(OR('La Mia Rosa'!$O$12="",$D2<>""),"",IF($F2<='La Mia Rosa'!$O$12*'Parametri Modello'!$B$24,"OK",IF($F2<='La Mia Rosa'!$O$12*'Parametri Modello'!$B$25,"Attenzione","Rischio Alto"))) -> Rischio Alto | V2: =IFERROR(COUNTIFS($B$2:$B$492,$B2,$O$2:$O$492,">"&$O2)+1,"") -> 1 | W2: ='Info Lega'!$B$4-SUMIFS($M$2:$M$492,$D$2:$D$492,'Info Lega'!$B$28) -> 1000 | X2: =('Info Lega'!$B$5-COUNTIFS($D$2:$D$492,'Info Lega'!$B$28,$B$2:$B$492,"P"))+('Info Lega'!$B$6-COUNTIFS($D$2:$D$492,'Info Lega'!$B$28,$B$2:$B$492,"D"))+('Info Lega'!$B$7-COUNTIFS($D$2:$D$492,'Info Lega'!$B$28,$B$2:$B$492,"C"))+('Info Lega'!$B$8-COUNTIFS($D$2:$D$492,'Info Lega'!$B$28,$B$2:$B$492,"A")) -> 25 | Y2: =X2*'Parametri Modello'!$B$30 -> 25 | Z2: =MAX(0,W2-Y2) -> 975 | AA2: =MIN(F2,Z2) -> 397 | AC2: =IF($AB2="","",IF($AB2>$AA2,"PASS",IF($AB2<=$AA2*(1-'Parametri Modello'!$B$68),"BID","ATTENZIONE"))) | AD2: =IF(I2="","",ROUND(100*(1-EXP(-I2/30)),0)) -> 63 | AE2: =IFERROR(IF($AF2="Titolare",INDEX('Stato Asta'!$G$9:$G$12,MATCH($B2,'Stato Asta'!$A$9:$A$12,0)),INDEX('Stato Asta'!$P$9:$P$12,MATCH($B2,'Stato Asta'!$A$9:$A$12,0))),"") -> 🟡 Attesa rischiosa | AF2: =IFERROR(IF($V2<=INDEX('Parametri Modello'!$C$57:$C$60,MATCH($B2,'Parametri Modello'!$A$57:$A$60,0)),"Titolare","Riserva"),"") -> Titolare | AG2: =IFERROR(INDEX('Pressione Competitiva'!$F$3:$F$6,MATCH($B2,'Pressione Competitiva'!$B$3:$B$6,0)),"") -> 🔴 Molto Alta | AH2: =IF($AB2="","",$AA2-$AB2) | AI2: =IFERROR(IF($AH2="","",IF($AH2>=$AA2*'Parametri Modello'!$B$68,"🟢 Opportunita'",IF($AH2<=$AA2*'Parametri Modello'!$B$69,"🔴 Sovrapprezzo","🟡 Prezzo Corretto"))),"") | AJ2: =IF($AB2="","",IF($AC2="PASS","Prezzo sopra la tua Offerta Max Dinamica ("&$AA2&" cr).",IF($AC2="BID","Margine ampio sul tuo tetto (+"&($AA2-$AB2)&" cr).","Margine ridotto: sei vicino al tuo tetto ("&($AA2-$AB2)&" cr residui)."))) | AK2: =IF(AND($D2="",$N2>1),COUNTIFS($B$2:$B$492,$B2,$P$2:$P$492,$P2,$D$2:$D$492,"",$N$2:$N$492,">1",$O$2:$O$492,">"&$O2)+1,"") -> 1 | AL2: =IF($AK2="","",$B2&"|"&$P2&"|"&$AK2) -> A|Top|1
A3: 5585 | B3: A | C3: Malen | E3: =IF(COUNTIF('Info Strategia'!$D$2:$D$51,$C3)>0,"SI","NO") -> NO | F3: =IFERROR(ROUND(($G3+($H3-$G3)*'Info Strategia'!$B$6)*(1+IF($E3="SI",'Parametri Modello'!$B$7*'Info Strategia'!$B$6,0)),0),"") -> 400 | G3: =IFERROR(ROUND(MAX(1,(IF($V3<=INDEX('Parametri Modello'!$C$57:$C$60,MATCH($B3,'Parametri Modello'!$A$57:$A$60,0)),IF(INDEX('Parametri Modello'!$E$57:$E$60,MATCH($B3,'Parametri Modello'!$A$57:$A$60,0))=0,0,($O3/INDEX('Parametri Modello'!$E$57:$E$60,MATCH($B3,'Parametri Modello'!$A$57:$A$60,0)))*(INDEX('Parametri Modello'!$D$57:$D$60,MATCH($B3,'Parametri Modello'!$A$57:$A$60,0))*(INDEX('Parametri Modello'!$B$50:$B$53,MATCH($B3,'Parametri Modello'!$A$50:$A$53,0))*'Parametri Modello'!$B$44))),IF(INDEX('Parametri Modello'!$F$57:$F$60,MATCH($B3,'Parametri Modello'!$A$57:$A$60,0))=0,0,($O3/INDEX('Parametri Modello'!$F$57:$F$60,MATCH($B3,'Parametri Modello'!$A$57:$A$60,0)))*((1-INDEX('Parametri Modello'!$D$57:$D$60,MATCH($B3,'Parametri Modello'!$A$57:$A$60,0)))*(INDEX('Parametri Modello'!$B$50:$B$53,MATCH($B3,'Parametri Modello'!$A$50:$A$53,0))*'Parametri Modello'!$B$44))))*(1+IF(IF($B3="D",'Info Lega'!$B$25,IF($B3="C",'Info Lega'!$B$26,"No"))="Si",'Parametri Modello'!$B$5,0))*(1+MAX(-0.25,MIN(0.25,IF(OR($T3="",$I3="",$I3=0,INDEX('Parametri Modello'!$B$19:$B$22,MATCH($B3,'Parametri Modello'!$A$19:$A$22,0))="",INDEX('Parametri Modello'!$B$19:$B$22,MATCH($B3,'Parametri Modello'!$A$19:$A$22,0))=0),0,(($T3-INDEX('Parametri Modello'!$B$19:$B$22,MATCH($B3,'Parametri Modello'!$A$19:$A$22,0)))/INDEX('Parametri Modello'!$B$19:$B$22,MATCH($B3,'Parametri Modello'!$A$19:$A$22,0)))*'Parametri Modello'!$B$9))))*(1+IF('Parametri Modello'!$B$27="Si",MAX(-'Parametri Modello'!$B$28,MIN('Parametri Modello'!$B$28*1.5,IF(OR(INDEX('Parametri Modello'!$F$32:$F$35,MATCH($B3,'Parametri Modello'!$A$32:$A$35,0))="",INDEX('Parametri Modello'!$F$32:$F$35,MATCH($B3,'Parametri Modello'!$A$32:$A$35,0))=0),0,(1/INDEX('Parametri Modello'!$F$32:$F$35,MATCH($B3,'Parametri Modello'!$A$32:$A$35,0))-1)*'Parametri Modello'!$B$28))),0)))*(1-INDEX('Parametri Modello'!$B$12:$B$15,MATCH($B3,'Parametri Modello'!$A$12:$A$15,0)))),0),"") -> 250 | H3: =IFERROR(ROUND((IF($V3<=INDEX('Parametri Modello'!$C$57:$C$60,MATCH($B3,'Parametri Modello'!$A$57:$A$60,0)),IF(INDEX('Parametri Modello'!$E$57:$E$60,MATCH($B3,'Parametri Modello'!$A$57:$A$60,0))=0,0,($O3/INDEX('Parametri Modello'!$E$57:$E$60,MATCH($B3,'Parametri Modello'!$A$57:$A$60,0)))*(INDEX('Parametri Modello'!$D$57:$D$60,MATCH($B3,'Parametri Modello'!$A$57:$A$60,0))*(INDEX('Parametri Modello'!$B$50:$B$53,MATCH($B3,'Parametri Modello'!$A$50:$A$53,0))*'Parametri Modello'!$B$44))),IF(INDEX('Parametri Modello'!$F$57:$F$60,MATCH($B3,'Parametri Modello'!$A$57:$A$60,0))=0,0,($O3/INDEX('Parametri Modello'!$F$57:$F$60,MATCH($B3,'Parametri Modello'!$A$57:$A$60,0)))*((1-INDEX('Parametri Modello'!$D$57:$D$60,MATCH($B3,'Parametri Modello'!$A$57:$A$60,0)))*(INDEX('Parametri Modello'!$B$50:$B$53,MATCH($B3,'Parametri Modello'!$A$50:$A$53,0))*'Parametri Modello'!$B$44))))*(1+IF(IF($B3="D",'Info Lega'!$B$25,IF($B3="C",'Info Lega'!$B$26,"No"))="Si",'Parametri Modello'!$B$5,0))*(1+MAX(-0.25,MIN(0.25,IF(OR($T3="",$I3="",$I3=0,INDEX('Parametri Modello'!$B$19:$B$22,MATCH($B3,'Parametri Modello'!$A$19:$A$22,0))="",INDEX('Parametri Modello'!$B$19:$B$22,MATCH($B3,'Parametri Modello'!$A$19:$A$22,0))=0),0,(($T3-INDEX('Parametri Modello'!$B$19:$B$22,MATCH($B3,'Parametri Modello'!$A$19:$A$22,0)))/INDEX('Parametri Modello'!$B$19:$B$22,MATCH($B3,'Parametri Modello'!$A$19:$A$22,0)))*'Parametri Modello'!$B$9))))*(1+IF('Parametri Modello'!$B$27="Si",MAX(-'Parametri Modello'!$B$28,MIN('Parametri Modello'!$B$28*1.5,IF(OR(INDEX('Parametri Modello'!$F$32:$F$35,MATCH($B3,'Parametri Modello'!$A$32:$A$35,0))="",INDEX('Parametri Modello'!$F$32:$F$35,MATCH($B3,'Parametri Modello'!$A$32:$A$35,0))=0),0,(1/INDEX('Parametri Modello'!$F$32:$F$35,MATCH($B3,'Parametri Modello'!$A$32:$A$35,0))-1)*'Parametri Modello'!$B$28))),0)))*(1+INDEX('Parametri Modello'!$B$12:$B$15,MATCH($B3,'Parametri Modello'!$A$12:$A$15,0))),0),"") -> 464 | I3: =IFERROR(INDEX('Input Statistiche 2025_26'!$F$3:$F$665,MATCH($A3,'Input Statistiche 2025_26'!$A$3:$A$665,0)),"") -> 18 | J3: =IFERROR(IF($I3="","",MAX(0,38-$I3)),"") -> 20 | K3: =IFERROR(INDEX('Input Statistiche 2025_26'!$I$3:$I$665,MATCH($A3,'Input Statistiche 2025_26'!$A$3:$A$665,0)),"") -> 14 | L3: =IFERROR(INDEX('Input Statistiche 2025_26'!$O$3:$O$665,MATCH($A3,'Input Statistiche 2025_26'!$A$3:$A$665,0)),"") -> 2 | N3: =IFERROR(INDEX('Input Giocatori 2026_27'!$E$3:$E$493,MATCH($A3,'Input Giocatori 2026_27'!$A$3:$A$493,0)),"") -> 34 | O3: =IFERROR(INDEX('Input Giocatori 2026_27'!$G$3:$G$493,MATCH($A3,'Input Giocatori 2026_27'!$A$3:$A$493,0)),"") -> 365 | P3: =IFERROR(IF($O3="","",IF((1-(COUNTIFS($B$2:$B$492,$B3,$O$2:$O$492,">"&$O3)+1-1)/COUNTIF($B$2:$B$492,$B3))>='Parametri Modello'!$B$63,"Top",IF((1-(COUNTIFS($B$2:$B$492,$B3,$O$2:$O$492,">"&$O3)+1-1)/COUNTIF($B$2:$B$492,$B3))>='Parametri Modello'!$B$64,"Buono",IF((1-(COUNTIFS($B$2:$B$492,$B3,$O$2:$O$492,">"&$O3)+1-1)/COUNTIF($B$2:$B$492,$B3))>='Parametri Modello'!$B$65,"Nella Media","Scommessa/Riserva")))),"") -> Top | Q3: =IF(AND($D3="",$N3>1),SUMPRODUCT(($D$2:$D3="")*($N$2:$N3>1)),"") -> 2 | R3: =IF($D3='Info Lega'!$B$28,COUNTIFS($D$2:$D3,'Info Lega'!$B$28),"") | S3: =IFERROR(INDEX('Input Statistiche 2025_26'!$G$3:$G$665,MATCH($A3,'Input Statistiche 2025_26'!$A$3:$A$665,0)),"") -> 6.72 | T3: =IFERROR(INDEX('Input Statistiche 2025_26'!$H$3:$H$665,MATCH($A3,'Input Statistiche 2025_26'!$A$3:$A$665,0)),"") -> 8.97 | U3: =IF(OR('La Mia Rosa'!$O$12="",$D3<>""),"",IF($F3<='La Mia Rosa'!$O$12*'Parametri Modello'!$B$24,"OK",IF($F3<='La Mia Rosa'!$O$12*'Parametri Modello'!$B$25,"Attenzione","Rischio Alto"))) -> Rischio Alto | V3: =IFERROR(COUNTIFS($B$2:$B$492,$B3,$O$2:$O$492,">"&$O3)+1,"") -> 2 | W3: ='Info Lega'!$B$4-SUMIFS($M$2:$M$492,$D$2:$D$492,'Info Lega'!$B$28) -> 1000 | X3: =('Info Lega'!$B$5-COUNTIFS($D$2:$D$492,'Info Lega'!$B$28,$B$2:$B$492,"P"))+('Info Lega'!$B$6-COUNTIFS($D$2:$D$492,'Info Lega'!$B$28,$B$2:$B$492,"D"))+('Info Lega'!$B$7-COUNTIFS($D$2:$D$492,'Info Lega'!$B$28,$B$2:$B$492,"C"))+('Info Lega'!$B$8-COUNTIFS($D$2:$D$492,'Info Lega'!$B$28,$B$2:$B$492,"A")) -> 25 | Y3: =X3*'Parametri Modello'!$B$30 -> 25 | Z3: =MAX(0,W3-Y3) -> 975 | AA3: =MIN(F3,Z3) -> 400 | AC3: =IF($AB3="","",IF($AB3>$AA3,"PASS",IF($AB3<=$AA3*(1-'Parametri Modello'!$B$68),"BID","ATTENZIONE"))) | AD3: =IF(I3="","",ROUND(100*(1-EXP(-I3/30)),0)) -> 45 | AE3: =IFERROR(IF($AF3="Titolare",INDEX('Stato Asta'!$G$9:$G$12,MATCH($B3,'Stato Asta'!$A$9:$A$12,0)),INDEX('Stato Asta'!$P$9:$P$12,MATCH($B3,'Stato Asta'!$A$9:$A$12,0))),"") -> 🟡 Attesa rischiosa | AF3: =IFERROR(IF($V3<=INDEX('Parametri Modello'!$C$57:$C$60,MATCH($B3,'Parametri Modello'!$A$57:$A$60,0)),"Titolare","Riserva"),"") -> Titolare | AG3: =IFERROR(INDEX('Pressione Competitiva'!$F$3:$F$6,MATCH($B3,'Pressione Competitiva'!$B$3:$B$6,0)),"") -> 🔴 Molto Alta | AH3: =IF($AB3="","",$AA3-$AB3) | AI3: =IFERROR(IF($AH3="","",IF($AH3>=$AA3*'Parametri Modello'!$B$68,"🟢 Opportunita'",IF($AH3<=$AA3*'Parametri Modello'!$B$69,"🔴 Sovrapprezzo","🟡 Prezzo Corretto"))),"") | AJ3: =IF($AB3="","",IF($AC3="PASS","Prezzo sopra la tua Offerta Max Dinamica ("&$AA3&" cr).",IF($AC3="BID","Margine ampio sul tuo tetto (+"&($AA3-$AB3)&" cr).","Margine ridotto: sei vicino al tuo tetto ("&($AA3-$AB3)&" cr residui)."))) | AK3: =IF(AND($D3="",$N3>1),COUNTIFS($B$2:$B$492,$B3,$P$2:$P$492,$P3,$D$2:$D$492,"",$N$2:$N$492,">1",$O$2:$O$492,">"&$O3)+1,"") -> 2 | AL3: =IF($AK3="","",$B3&"|"&$P3&"|"&$AK3) -> A|Top|2
A4: 4871 | B4: A | C4: Thuram | E4: =IF(COUNTIF('Info Strategia'!$D$2:$D$51,$C4)>0,"SI","NO") -> NO | F4: =IFERROR(ROUND(($G4+($H4-$G4)*'Info Strategia'!$B$6)*(1+IF($E4="SI",'Parametri Modello'!$B$7*'Info Strategia'!$B$6,0)),0),"") -> 298 | G4: =IFERROR(ROUND(MAX(1,(IF($V4<=INDEX('Parametri Modello'!$C$57:$C$60,MATCH($B4,'Parametri Modello'!$A$57:$A$60,0)),IF(INDEX('Parametri Modello'!$E$57:$E$60,MATCH($B4,'Parametri Modello'!$A$57:$A$60,0))=0,0,($O4/INDEX('Parametri Modello'!$E$57:$E$60,MATCH($B4,'Parametri Modello'!$A$57:$A$60,0)))*(INDEX('Parametri Modello'!$D$57:$D$60,MATCH($B4,'Parametri Modello'!$A$57:$A$60,0))*(INDEX('Parametri Modello'!$B$50:$B$53,MATCH($B4,'Parametri Modello'!$A$50:$A$53,0))*'Parametri Modello'!$B$44))),IF(INDEX('Parametri Modello'!$F$57:$F$60,MATCH($B4,'Parametri Modello'!$A$57:$A$60,0))=0,0,($O4/INDEX('Parametri Modello'!$F$57:$F$60,MATCH($B4,'Parametri Modello'!$A$57:$A$60,0)))*((1-INDEX('Parametri Modello'!$D$57:$D$60,MATCH($B4,'Parametri Modello'!$A$57:$A$60,0)))*(INDEX('Parametri Modello'!$B$50:$B$53,MATCH($B4,'Parametri Modello'!$A$50:$A$53,0))*'Parametri Modello'!$B$44))))*(1+IF(IF($B4="D",'Info Lega'!$B$25,IF($B4="C",'Info Lega'!$B$26,"No"))="Si",'Parametri Modello'!$B$5,0))*(1+MAX(-0.25,MIN(0.25,IF(OR($T4="",$I4="",$I4=0,INDEX('Parametri Modello'!$B$19:$B$22,MATCH($B4,'Parametri Modello'!$A$19:$A$22,0))="",INDEX('Parametri Modello'!$B$19:$B$22,MATCH($B4,'Parametri Modello'!$A$19:$A$22,0))=0),0,(($T4-INDEX('Parametri Modello'!$B$19:$B$22,MATCH($B4,'Parametri Modello'!$A$19:$A$22,0)))/INDEX('Parametri Modello'!$B$19:$B$22,MATCH($B4,'Parametri Modello'!$A$19:$A$22,0)))*'Parametri Modello'!$B$9))))*(1+IF('Parametri Modello'!$B$27="Si",MAX(-'Parametri Modello'!$B$28,MIN('Parametri Modello'!$B$28*1.5,IF(OR(INDEX('Parametri Modello'!$F$32:$F$35,MATCH($B4,'Parametri Modello'!$A$32:$A$35,0))="",INDEX('Parametri Modello'!$F$32:$F$35,MATCH($B4,'Parametri Modello'!$A$32:$A$35,0))=0),0,(1/INDEX('Parametri Modello'!$F$32:$F$35,MATCH($B4,'Parametri Modello'!$A$32:$A$35,0))-1)*'Parametri Modello'!$B$28))),0)))*(1-INDEX('Parametri Modello'!$B$12:$B$15,MATCH($B4,'Parametri Modello'!$A$12:$A$15,0)))),0),"") -> 186 | H4: =IFERROR(ROUND((IF($V4<=INDEX('Parametri Modello'!$C$57:$C$60,MATCH($B4,'Parametri Modello'!$A$57:$A$60,0)),IF(INDEX('Parametri Modello'!$E$57:$E$60,MATCH($B4,'Parametri Modello'!$A$57:$A$60,0))=0,0,($O4/INDEX('Parametri Modello'!$E$57:$E$60,MATCH($B4,'Parametri Modello'!$A$57:$A$60,0)))*(INDEX('Parametri Modello'!$D$57:$D$60,MATCH($B4,'Parametri Modello'!$A$57:$A$60,0))*(INDEX('Parametri Modello'!$B$50:$B$53,MATCH($B4,'Parametri Modello'!$A$50:$A$53,0))*'Parametri Modello'!$B$44))),IF(INDEX('Parametri Modello'!$F$57:$F$60,MATCH($B4,'Parametri Modello'!$A$57:$A$60,0))=0,0,($O4/INDEX('Parametri Modello'!$F$57:$F$60,MATCH($B4,'Parametri Modello'!$A$57:$A$60,0)))*((1-INDEX('Parametri Modello'!$D$57:$D$60,MATCH($B4,'Parametri Modello'!$A$57:$A$60,0)))*(INDEX('Parametri Modello'!$B$50:$B$53,MATCH($B4,'Parametri Modello'!$A$50:$A$53,0))*'Parametri Modello'!$B$44))))*(1+IF(IF($B4="D",'Info Lega'!$B$25,IF($B4="C",'Info Lega'!$B$26,"No"))="Si",'Parametri Modello'!$B$5,0))*(1+MAX(-0.25,MIN(0.25,IF(OR($T4="",$I4="",$I4=0,INDEX('Parametri Modello'!$B$19:$B$22,MATCH($B4,'Parametri Modello'!$A$19:$A$22,0))="",INDEX('Parametri Modello'!$B$19:$B$22,MATCH($B4,'Parametri Modello'!$A$19:$A$22,0))=0),0,(($T4-INDEX('Parametri Modello'!$B$19:$B$22,MATCH($B4,'Parametri Modello'!$A$19:$A$22,0)))/INDEX('Parametri Modello'!$B$19:$B$22,MATCH($B4,'Parametri Modello'!$A$19:$A$22,0)))*'Parametri Modello'!$B$9))))*(1+IF('Parametri Modello'!$B$27="Si",MAX(-'Parametri Modello'!$B$28,MIN('Parametri Modello'!$B$28*1.5,IF(OR(INDEX('Parametri Modello'!$F$32:$F$35,MATCH($B4,'Parametri Modello'!$A$32:$A$35,0))="",INDEX('Parametri Modello'!$F$32:$F$35,MATCH($B4,'Parametri Modello'!$A$32:$A$35,0))=0),0,(1/INDEX('Parametri Modello'!$F$32:$F$35,MATCH($B4,'Parametri Modello'!$A$32:$A$35,0))-1)*'Parametri Modello'!$B$28))),0)))*(1+INDEX('Parametri Modello'!$B$12:$B$15,MATCH($B4,'Parametri Modello'!$A$12:$A$15,0))),0),"") -> 346 | I4: =IFERROR(INDEX('Input Statistiche 2025_26'!$F$3:$F$665,MATCH($A4,'Input Statistiche 2025_26'!$A$3:$A$665,0)),"") -> 29 | J4: =IFERROR(IF($I4="","",MAX(0,38-$I4)),"") -> 9 | K4: =IFERROR(INDEX('Input Statistiche 2025_26'!$I$3:$I$665,MATCH($A4,'Input Statistiche 2025_26'!$A$3:$A$665,0)),"") -> 13 | L4: =IFERROR(INDEX('Input Statistiche 2025_26'!$O$3:$O$665,MATCH($A4,'Input Statistiche 2025_26'!$A$3:$A$665,0)),"") -> 6 | N4: =IFERROR(INDEX('Input Giocatori 2026_27'!$E$3:$E$493,MATCH($A4,'Input Giocatori 2026_27'!$A$3:$A$493,0)),"") -> 29 | O4: =IFERROR(INDEX('Input Giocatori 2026_27'!$G$3:$G$493,MATCH($A4,'Input Giocatori 2026_27'!$A$3:$A$493,0)),"") -> 280 | P4: =IFERROR(IF($O4="","",IF((1-(COUNTIFS($B$2:$B$492,$B4,$O$2:$O$492,">"&$O4)+1-1)/COUNTIF($B$2:$B$492,$B4))>='Parametri Modello'!$B$63,"Top",IF((1-(COUNTIFS($B$2:$B$492,$B4,$O$2:$O$492,">"&$O4)+1-1)/COUNTIF($B$2:$B$492,$B4))>='Parametri Modello'!$B$64,"Buono",IF((1-(COUNTIFS($B$2:$B$492,$B4,$O$2:$O$492,">"&$O4)+1-1)/COUNTIF($B$2:$B$492,$B4))>='Parametri Modello'!$B$65,"Nella Media","Scommessa/Riserva")))),"") -> Top | Q4: =IF(AND($D4="",$N4>1),SUMPRODUCT(($D$2:$D4="")*($N$2:$N4>1)),"") -> 3 | R4: =IF($D4='Info Lega'!$B$28,COUNTIFS($D$2:$D4,'Info Lega'!$B$28),"") | S4: =IFERROR(INDEX('Input Statistiche 2025_26'!$G$3:$G$665,MATCH($A4,'Input Statistiche 2025_26'!$A$3:$A$665,0)),"") -> 6.43 | T4: =IFERROR(INDEX('Input Statistiche 2025_26'!$H$3:$H$665,MATCH($A4,'Input Statistiche 2025_26'!$A$3:$A$665,0)),"") -> 7.95 | U4: =IF(OR('La Mia Rosa'!$O$12="",$D4<>""),"",IF($F4<='La Mia Rosa'!$O$12*'Parametri Modello'!$B$24,"OK",IF($F4<='La Mia Rosa'!$O$12*'Parametri Modello'!$B$25,"Attenzione","Rischio Alto"))) -> Rischio Alto | V4: =IFERROR(COUNTIFS($B$2:$B$492,$B4,$O$2:$O$492,">"&$O4)+1,"") -> 3 | W4: ='Info Lega'!$B$4-SUMIFS($M$2:$M$492,$D$2:$D$492,'Info Lega'!$B$28) -> 1000 | X4: =('Info Lega'!$B$5-COUNTIFS($D$2:$D$492,'Info Lega'!$B$28,$B$2:$B$492,"P"))+('Info Lega'!$B$6-COUNTIFS($D$2:$D$492,'Info Lega'!$B$28,$B$2:$B$492,"D"))+('Info Lega'!$B$7-COUNTIFS($D$2:$D$492,'Info Lega'!$B$28,$B$2:$B$492,"C"))+('Info Lega'!$B$8-COUNTIFS($D$2:$D$492,'Info Lega'!$B$28,$B$2:$B$492,"A")) -> 25 | Y4: =X4*'Parametri Modello'!$B$30 -> 25 | Z4: =MAX(0,W4-Y4) -> 975 | AA4: =MIN(F4,Z4) -> 298 | AC4: =IF($AB4="","",IF($AB4>$AA4,"PASS",IF($AB4<=$AA4*(1-'Parametri Modello'!$B$68),"BID","ATTENZIONE"))) | AD4: =IF(I4="","",ROUND(100*(1-EXP(-I4/30)),0)) -> 62 | AE4: =IFERROR(IF($AF4="Titolare",INDEX('Stato Asta'!$G$9:$G$12,MATCH($B4,'Stato Asta'!$A$9:$A$12,0)),INDEX('Stato Asta'!$P$9:$P$12,MATCH($B4,'Stato Asta'!$A$9:$A$12,0))),"") -> 🟡 Attesa rischiosa | AF4: =IFERROR(IF($V4<=INDEX('Parametri Modello'!$C$57:$C$60,MATCH($B4,'Parametri Modello'!$A$57:$A$60,0)),"Titolare","Riserva"),"") -> Titolare | AG4: =IFERROR(INDEX('Pressione Competitiva'!$F$3:$F$6,MATCH($B4,'Pressione Competitiva'!$B$3:$B$6,0)),"") -> 🔴 Molto Alta | AH4: =IF($AB4="","",$AA4-$AB4) | AI4: =IFERROR(IF($AH4="","",IF($AH4>=$AA4*'Parametri Modello'!$B$68,"🟢 Opportunita'",IF($AH4<=$AA4*'Parametri Modello'!$B$69,"🔴 Sovrapprezzo","🟡 Prezzo Corretto"))),"") | AJ4: =IF($AB4="","",IF($AC4="PASS","Prezzo sopra la tua Offerta Max Dinamica ("&$AA4&" cr).",IF($AC4="BID","Margine ampio sul tuo tetto (+"&($AA4-$AB4)&" cr).","Margine ridotto: sei vicino al tuo tetto ("&($AA4-$AB4)&" cr residui)."))) | AK4: =IF(AND($D4="",$N4>1),COUNTIFS($B$2:$B$492,$B4,$P$2:$P$492,$P4,$D$2:$D$492,"",$N$2:$N$492,">1",$O$2:$O$492,">"&$O4)+1,"") -> 3 | AL4: =IF($AK4="","",$B4&"|"&$P4&"|"&$AK4) -> A|Top|3
A5: 6052 | B5: A | C5: Hojlund | E5: =IF(COUNTIF('Info Strategia'!$D$2:$D$51,$C5)>0,"SI","NO") -> NO | F5: =IFERROR(ROUND(($G5+($H5-$G5)*'Info Strategia'!$B$6)*(1+IF($E5="SI",'Parametri Modello'!$B$7*'Info Strategia'!$B$6,0)),0),"") -> 284 | G5: =IFERROR(ROUND(MAX(1,(IF($V5<=INDEX('Parametri Modello'!$C$57:$C$60,MATCH($B5,'Parametri Modello'!$A$57:$A$60,0)),IF(INDEX('Parametri Modello'!$E$57:$E$60,MATCH($B5,'Parametri Modello'!$A$57:$A$60,0))=0,0,($O5/INDEX('Parametri Modello'!$E$57:$E$60,MATCH($B5,'Parametri Modello'!$A$57:$A$60,0)))*(INDEX('Parametri Modello'!$D$57:$D$60,MATCH($B5,'Parametri Modello'!$A$57:$A$60,0))*(INDEX('Parametri Modello'!$B$50:$B$53,MATCH($B5,'Parametri Modello'!$A$50:$A$53,0))*'Parametri Modello'!$B$44))),IF(INDEX('Parametri Modello'!$F$57:$F$60,MATCH($B5,'Parametri Modello'!$A$57:$A$60,0))=0,0,($O5/INDEX('Parametri Modello'!$F$57:$F$60,MATCH($B5,'Parametri Modello'!$A$57:$A$60,0)))*((1-INDEX('Parametri Modello'!$D$57:$D$60,MATCH($B5,'Parametri Modello'!$A$57:$A$60,0)))*(INDEX('Parametri Modello'!$B$50:$B$53,MATCH($B5,'Parametri Modello'!$A$50:$A$53,0))*'Parametri Modello'!$B$44))))*(1+IF(IF($B5="D",'Info Lega'!$B$25,IF($B5="C",'Info Lega'!$B$26,"No"))="Si",'Parametri Modello'!$B$5,0))*(1+MAX(-0.25,MIN(0.25,IF(OR($T5="",$I5="",$I5=0,INDEX('Parametri Modello'!$B$19:$B$22,MATCH($B5,'Parametri Modello'!$A$19:$A$22,0))="",INDEX('Parametri Modello'!$B$19:$B$22,MATCH($B5,'Parametri Modello'!$A$19:$A$22,0))=0),0,(($T5-INDEX('Parametri Modello'!$B$19:$B$22,MATCH($B5,'Parametri Modello'!$A$19:$A$22,0)))/INDEX('Parametri Modello'!$B$19:$B$22,MATCH($B5,'Parametri Modello'!$A$19:$A$22,0)))*'Parametri Modello'!$B$9))))*(1+IF('Parametri Modello'!$B$27="Si",MAX(-'Parametri Modello'!$B$28,MIN('Parametri Modello'!$B$28*1.5,IF(OR(INDEX('Parametri Modello'!$F$32:$F$35,MATCH($B5,'Parametri Modello'!$A$32:$A$35,0))="",INDEX('Parametri Modello'!$F$32:$F$35,MATCH($B5,'Parametri Modello'!$A$32:$A$35,0))=0),0,(1/INDEX('Parametri Modello'!$F$32:$F$35,MATCH($B5,'Parametri Modello'!$A$32:$A$35,0))-1)*'Parametri Modello'!$B$28))),0)))*(1-INDEX('Parametri Modello'!$B$12:$B$15,MATCH($B5,'Parametri Modello'!$A$12:$A$15,0)))),0),"") -> 178 | H5: =IFERROR(ROUND((IF($V5<=INDEX('Parametri Modello'!$C$57:$C$60,MATCH($B5,'Parametri Modello'!$A$57:$A$60,0)),IF(INDEX('Parametri Modello'!$E$57:$E$60,MATCH($B5,'Parametri Modello'!$A$57:$A$60,0))=0,0,($O5/INDEX('Parametri Modello'!$E$57:$E$60,MATCH($B5,'Parametri Modello'!$A$57:$A$60,0)))*(INDEX('Parametri Modello'!$D$57:$D$60,MATCH($B5,'Parametri Modello'!$A$57:$A$60,0))*(INDEX('Parametri Modello'!$B$50:$B$53,MATCH($B5,'Parametri Modello'!$A$50:$A$53,0))*'Parametri Modello'!$B$44))),IF(INDEX('Parametri Modello'!$F$57:$F$60,MATCH($B5,'Parametri Modello'!$A$57:$A$60,0))=0,0,($O5/INDEX('Parametri Modello'!$F$57:$F$60,MATCH($B5,'Parametri Modello'!$A$57:$A$60,0)))*((1-INDEX('Parametri Modello'!$D$57:$D$60,MATCH($B5,'Parametri Modello'!$A$57:$A$60,0)))*(INDEX('Parametri Modello'!$B$50:$B$53,MATCH($B5,'Parametri Modello'!$A$50:$A$53,0))*'Parametri Modello'!$B$44))))*(1+IF(IF($B5="D",'Info Lega'!$B$25,IF($B5="C",'Info Lega'!$B$26,"No"))="Si",'Parametri Modello'!$B$5,0))*(1+MAX(-0.25,MIN(0.25,IF(OR($T5="",$I5="",$I5=0,INDEX('Parametri Modello'!$B$19:$B$22,MATCH($B5,'Parametri Modello'!$A$19:$A$22,0))="",INDEX('Parametri Modello'!$B$19:$B$22,MATCH($B5,'Parametri Modello'!$A$19:$A$22,0))=0),0,(($T5-INDEX('Parametri Modello'!$B$19:$B$22,MATCH($B5,'Parametri Modello'!$A$19:$A$22,0)))/INDEX('Parametri Modello'!$B$19:$B$22,MATCH($B5,'Parametri Modello'!$A$19:$A$22,0)))*'Parametri Modello'!$B$9))))*(1+IF('Parametri Modello'!$B$27="Si",MAX(-'Parametri Modello'!$B$28,MIN('Parametri Modello'!$B$28*1.5,IF(OR(INDEX('Parametri Modello'!$F$32:$F$35,MATCH($B5,'Parametri Modello'!$A$32:$A$35,0))="",INDEX('Parametri Modello'!$F$32:$F$35,MATCH($B5,'Parametri Modello'!$A$32:$A$35,0))=0),0,(1/INDEX('Parametri Modello'!$F$32:$F$35,MATCH($B5,'Parametri Modello'!$A$32:$A$35,0))-1)*'Parametri Modello'!$B$28))),0)))*(1+INDEX('Parametri Modello'!$B$12:$B$15,MATCH($B5,'Parametri Modello'!$A$12:$A$15,0))),0),"") -> 330 | I5: =IFERROR(INDEX('Input Statistiche 2025_26'!$F$3:$F$665,MATCH($A5,'Input Statistiche 2025_26'!$A$3:$A$665,0)),"") -> 33 | J5: =IFERROR(IF($I5="","",MAX(0,38-$I5)),"") -> 5 | K5: =IFERROR(INDEX('Input Statistiche 2025_26'!$I$3:$I$665,MATCH($A5,'Input Statistiche 2025_26'!$A$3:$A$665,0)),"") -> 12 | L5: =IFERROR(INDEX('Input Statistiche 2025_26'!$O$3:$O$665,MATCH($A5,'Input Statistiche 2025_26'!$A$3:$A$665,0)),"") -> 5 | N5: =IFERROR(INDEX('Input Giocatori 2026_27'!$E$3:$E$493,MATCH($A5,'Input Giocatori 2026_27'!$A$3:$A$493,0)),"") -> 28 | O5: =IFERROR(INDEX('Input Giocatori 2026_27'!$G$3:$G$493,MATCH($A5,'Input Giocatori 2026_27'!$A$3:$A$493,0)),"") -> 271 | P5: =IFERROR(IF($O5="","",IF((1-(COUNTIFS($B$2:$B$492,$B5,$O$2:$O$492,">"&$O5)+1-1)/COUNTIF($B$2:$B$492,$B5))>='Parametri Modello'!$B$63,"Top",IF((1-(COUNTIFS($B$2:$B$492,$B5,$O$2:$O$492,">"&$O5)+1-1)/COUNTIF($B$2:$B$492,$B5))>='Parametri Modello'!$B$64,"Buono",IF((1-(COUNTIFS($B$2:$B$492,$B5,$O$2:$O$492,">"&$O5)+1-1)/COUNTIF($B$2:$B$492,$B5))>='Parametri Modello'!$B$65,"Nella Media","Scommessa/Riserva")))),"") -> Top | Q5: =IF(AND($D5="",$N5>1),SUMPRODUCT(($D$2:$D5="")*($N$2:$N5>1)),"") -> 4 | R5: =IF($D5='Info Lega'!$B$28,COUNTIFS($D$2:$D5,'Info Lega'!$B$28),"") | S5: =IFERROR(INDEX('Input Statistiche 2025_26'!$G$3:$G$665,MATCH($A5,'Input Statistiche 2025_26'!$A$3:$A$665,0)),"") -> 6.21 | T5: =IFERROR(INDEX('Input Statistiche 2025_26'!$H$3:$H$665,MATCH($A5,'Input Statistiche 2025_26'!$A$3:$A$665,0)),"") -> 7.44 | U5: =IF(OR('La Mia Rosa'!$O$12="",$D5<>""),"",IF($F5<='La Mia Rosa'!$O$12*'Parametri Modello'!$B$24,"OK",IF($F5<='La Mia Rosa'!$O$12*'Parametri Modello'!$B$25,"Attenzione","Rischio Alto"))) -> Rischio Alto | V5: =IFERROR(COUNTIFS($B$2:$B$492,$B5,$O$2:$O$492,">"&$O5)+1,"") -> 4 | W5: ='Info Lega'!$B$4-SUMIFS($M$2:$M$492,$D$2:$D$492,'Info Lega'!$B$28) -> 1000 | X5: =('Info Lega'!$B$5-COUNTIFS($D$2:$D$492,'Info Lega'!$B$28,$B$2:$B$492,"P"))+('Info Lega'!$B$6-COUNTIFS($D$2:$D$492,'Info Lega'!$B$28,$B$2:$B$492,"D"))+('Info Lega'!$B$7-COUNTIFS($D$2:$D$492,'Info Lega'!$B$28,$B$2:$B$492,"C"))+('Info Lega'!$B$8-COUNTIFS($D$2:$D$492,'Info Lega'!$B$28,$B$2:$B$492,"A")) -> 25 | Y5: =X5*'Parametri Modello'!$B$30 -> 25 | Z5: =MAX(0,W5-Y5) -> 975 | AA5: =MIN(F5,Z5) -> 284 | AC5: =IF($AB5="","",IF($AB5>$AA5,"PASS",IF($AB5<=$AA5*(1-'Parametri Modello'!$B$68),"BID","ATTENZIONE"))) | AD5: =IF(I5="","",ROUND(100*(1-EXP(-I5/30)),0)) -> 67 | AE5: =IFERROR(IF($AF5="Titolare",INDEX('Stato Asta'!$G$9:$G$12,MATCH($B5,'Stato Asta'!$A$9:$A$12,0)),INDEX('Stato Asta'!$P$9:$P$12,MATCH($B5,'Stato Asta'!$A$9:$A$12,0))),"") -> 🟡 Attesa rischiosa | AF5: =IFERROR(IF($V5<=INDEX('Parametri Modello'!$C$57:$C$60,MATCH($B5,'Parametri Modello'!$A$57:$A$60,0)),"Titolare","Riserva"),"") -> Titolare | AG5: =IFERROR(INDEX('Pressione Competitiva'!$F$3:$F$6,MATCH($B5,'Pressione Competitiva'!$B$3:$B$6,0)),"") -> 🔴 Molto Alta | AH5: =IF($AB5="","",$AA5-$AB5) | AI5: =IFERROR(IF($AH5="","",IF($AH5>=$AA5*'Parametri Modello'!$B$68,"🟢 Opportunita'",IF($AH5<=$AA5*'Parametri Modello'!$B$69,"🔴 Sovrapprezzo","🟡 Prezzo Corretto"))),"") | AJ5: =IF($AB5="","",IF($AC5="PASS","Prezzo sopra la tua Offerta Max Dinamica ("&$AA5&" cr).",IF($AC5="BID","Margine ampio sul tuo tetto (+"&($AA5-$AB5)&" cr).","Margine ridotto: sei vicino al tuo tetto ("&($AA5-$AB5)&" cr residui)."))) | AK5: =IF(AND($D5="",$N5>1),COUNTIFS($B$2:$B$492,$B5,$P$2:$P$492,$P5,$D$2:$D$492,"",$N$2:$N$492,">1",$O$2:$O$492,">"&$O5)+1,"") -> 4 | AL5: =IF($AK5="","",$B5&"|"&$P5&"|"&$AK5) -> A|Top|4
A6: 254 | B6: D | C6: Dimarco | E6: =IF(COUNTIF('Info Strategia'!$D$2:$D$51,$C6)>0,"SI","NO") -> NO | F6: =IFERROR(ROUND(($G6+($H6-$G6)*'Info Strategia'!$B$6)*(1+IF($E6="SI",'Parametri Modello'!$B$7*'Info Strategia'!$B$6,0)),0),"") -> 190 | G6: =IFERROR(ROUND(MAX(1,(IF($V6<=INDEX('Parametri Modello'!$C$57:$C$60,MATCH($B6,'Parametri Modello'!$A$57:$A$60,0)),IF(INDEX('Parametri Modello'!$E$57:$E$60,MATCH($B6,'Parametri Modello'!$A$57:$A$60,0))=0,0,($O6/INDEX('Parametri Modello'!$E$57:$E$60,MATCH($B6,'Parametri Modello'!$A$57:$A$60,0)))*(INDEX('Parametri Modello'!$D$57:$D$60,MATCH($B6,'Parametri Modello'!$A$57:$A$60,0))*(INDEX('Parametri Modello'!$B$50:$B$53,MATCH($B6,'Parametri Modello'!$A$50:$A$53,0))*'Parametri Modello'!$B$44))),IF(INDEX('Parametri Modello'!$F$57:$F$60,MATCH($B6,'Parametri Modello'!$A$57:$A$60,0))=0,0,($O6/INDEX('Parametri Modello'!$F$57:$F$60,MATCH($B6,'Parametri Modello'!$A$57:$A$60,0)))*((1-INDEX('Parametri Modello'!$D$57:$D$60,MATCH($B6,'Parametri Modello'!$A$57:$A$60,0)))*(INDEX('Parametri Modello'!$B$50:$B$53,MATCH($B6,'Parametri Modello'!$A$50:$A$53,0))*'Parametri Modello'!$B$44))))*(1+IF(IF($B6="D",'Info Lega'!$B$25,IF($B6="C",'Info Lega'!$B$26,"No"))="Si",'Parametri Modello'!$B$5,0))*(1+MAX(-0.25,MIN(0.25,IF(OR($T6="",$I6="",$I6=0,INDEX('Parametri Modello'!$B$19:$B$22,MATCH($B6,'Parametri Modello'!$A$19:$A$22,0))="",INDEX('Parametri Modello'!$B$19:$B$22,MATCH($B6,'Parametri Modello'!$A$19:$A$22,0))=0),0,(($T6-INDEX('Parametri Modello'!$B$19:$B$22,MATCH($B6,'Parametri Modello'!$A$19:$A$22,0)))/INDEX('Parametri Modello'!$B$19:$B$22,MATCH($B6,'Parametri Modello'!$A$19:$A$22,0)))*'Parametri Modello'!$B$9))))*(1+IF('Parametri Modello'!$B$27="Si",MAX(-'Parametri Modello'!$B$28,MIN('Parametri Modello'!$B$28*1.5,IF(OR(INDEX('Parametri Modello'!$F$32:$F$35,MATCH($B6,'Parametri Modello'!$A$32:$A$35,0))="",INDEX('Parametri Modello'!$F$32:$F$35,MATCH($B6,'Parametri Modello'!$A$32:$A$35,0))=0),0,(1/INDEX('Parametri Modello'!$F$32:$F$35,MATCH($B6,'Parametri Modello'!$A$32:$A$35,0))-1)*'Parametri Modello'!$B$28))),0)))*(1-INDEX('Parametri Modello'!$B$12:$B$15,MATCH($B6,'Parametri Modello'!$A$12:$A$15,0)))),0),"") -> 141 | H6: =IFERROR(ROUND((IF($V6<=INDEX('Parametri Modello'!$C$57:$C$60,MATCH($B6,'Parametri Modello'!$A$57:$A$60,0)),IF(INDEX('Parametri Modello'!$E$57:$E$60,MATCH($B6,'Parametri Modello'!$A$57:$A$60,0))=0,0,($O6/INDEX('Parametri Modello'!$E$57:$E$60,MATCH($B6,'Parametri Modello'!$A$57:$A$60,0)))*(INDEX('Parametri Modello'!$D$57:$D$60,MATCH($B6,'Parametri Modello'!$A$57:$A$60,0))*(INDEX('Parametri Modello'!$B$50:$B$53,MATCH($B6,'Parametri Modello'!$A$50:$A$53,0))*'Parametri Modello'!$B$44))),IF(INDEX('Parametri Modello'!$F$57:$F$60,MATCH($B6,'Parametri Modello'!$A$57:$A$60,0))=0,0,($O6/INDEX('Parametri Modello'!$F$57:$F$60,MATCH($B6,'Parametri Modello'!$A$57:$A$60,0)))*((1-INDEX('Parametri Modello'!$D$57:$D$60,MATCH($B6,'Parametri Modello'!$A$57:$A$60,0)))*(INDEX('Parametri Modello'!$B$50:$B$53,MATCH($B6,'Parametri Modello'!$A$50:$A$53,0))*'Parametri Modello'!$B$44))))*(1+IF(IF($B6="D",'Info Lega'!$B$25,IF($B6="C",'Info Lega'!$B$26,"No"))="Si",'Parametri Modello'!$B$5,0))*(1+MAX(-0.25,MIN(0.25,IF(OR($T6="",$I6="",$I6=0,INDEX('Parametri Modello'!$B$19:$B$22,MATCH($B6,'Parametri Modello'!$A$19:$A$22,0))="",INDEX('Parametri Modello'!$B$19:$B$22,MATCH($B6,'Parametri Modello'!$A$19:$A$22,0))=0),0,(($T6-INDEX('Parametri Modello'!$B$19:$B$22,MATCH($B6,'Parametri Modello'!$A$19:$A$22,0)))/INDEX('Parametri Modello'!$B$19:$B$22,MATCH($B6,'Parametri Modello'!$A$19:$A$22,0)))*'Parametri Modello'!$B$9))))*(1+IF('Parametri Modello'!$B$27="Si",MAX(-'Parametri Modello'!$B$28,MIN('Parametri Modello'!$B$28*1.5,IF(OR(INDEX('Parametri Modello'!$F$32:$F$35,MATCH($B6,'Parametri Modello'!$A$32:$A$35,0))="",INDEX('Parametri Modello'!$F$32:$F$35,MATCH($B6,'Parametri Modello'!$A$32:$A$35,0))=0),0,(1/INDEX('Parametri Modello'!$F$32:$F$35,MATCH($B6,'Parametri Modello'!$A$32:$A$35,0))-1)*'Parametri Modello'!$B$28))),0)))*(1+INDEX('Parametri Modello'!$B$12:$B$15,MATCH($B6,'Parametri Modello'!$A$12:$A$15,0))),0),"") -> 211 | I6: =IFERROR(INDEX('Input Statistiche 2025_26'!$F$3:$F$665,MATCH($A6,'Input Statistiche 2025_26'!$A$3:$A$665,0)),"") -> 35 | J6: =IFERROR(IF($I6="","",MAX(0,38-$I6)),"") -> 3 | K6: =IFERROR(INDEX('Input Statistiche 2025_26'!$I$3:$I$665,MATCH($A6,'Input Statistiche 2025_26'!$A$3:$A$665,0)),"") -> 7 | L6: =IFERROR(INDEX('Input Statistiche 2025_26'!$O$3:$O$665,MATCH($A6,'Input Statistiche 2025_26'!$A$3:$A$665,0)),"") -> 17 | N6: =IFERROR(INDEX('Input Giocatori 2026_27'!$E$3:$E$493,MATCH($A6,'Input Giocatori 2026_27'!$A$3:$A$493,0)),"") -> 32 | O6: =IFERROR(INDEX('Input Giocatori 2026_27'!$G$3:$G$493,MATCH($A6,'Input Giocatori 2026_27'!$A$3:$A$493,0)),"") -> 265 | P6: =IFERROR(IF($O6="","",IF((1-(COUNTIFS($B$2:$B$492,$B6,$O$2:$O$492,">"&$O6)+1-1)/COUNTIF($B$2:$B$492,$B6))>='Parametri Modello'!$B$63,"Top",IF((1-(COUNTIFS($B$2:$B$492,$B6,$O$2:$O$492,">"&$O6)+1-1)/COUNTIF($B$2:$B$492,$B6))>='Parametri Modello'!$B$64,"Buono",IF((1-(COUNTIFS($B$2:$B$492,$B6,$O$2:$O$492,">"&$O6)+1-1)/COUNTIF($B$2:$B$492,$B6))>='Parametri Modello'!$B$65,"Nella Media","Scommessa/Riserva")))),"") -> Top | Q6: =IF(AND($D6="",$N6>1),SUMPRODUCT(($D$2:$D6="")*($N$2:$N6>1)),"") -> 5 | R6: =IF($D6='Info Lega'!$B$28,COUNTIFS($D$2:$D6,'Info Lega'!$B$28),"") | S6: =IFERROR(INDEX('Input Statistiche 2025_26'!$G$3:$G$665,MATCH($A6,'Input Statistiche 2025_26'!$A$3:$A$665,0)),"") -> 6.6 | T6: =IFERROR(INDEX('Input Statistiche 2025_26'!$H$3:$H$665,MATCH($A6,'Input Statistiche 2025_26'!$A$3:$A$665,0)),"") -> 7.64 | U6: =IF(OR('La Mia Rosa'!$O$12="",$D6<>""),"",IF($F6<='La Mia Rosa'!$O$12*'Parametri Modello'!$B$24,"OK",IF($F6<='La Mia Rosa'!$O$12*'Parametri Modello'!$B$25,"Attenzione","Rischio Alto"))) -> Rischio Alto | V6: =IFERROR(COUNTIFS($B$2:$B$492,$B6,$O$2:$O$492,">"&$O6)+1,"") -> 1 | W6: ='Info Lega'!$B$4-SUMIFS($M$2:$M$492,$D$2:$D$492,'Info Lega'!$B$28) -> 1000 | X6: =('Info Lega'!$B$5-COUNTIFS($D$2:$D$492,'Info Lega'!$B$28,$B$2:$B$492,"P"))+('Info Lega'!$B$6-COUNTIFS($D$2:$D$492,'Info Lega'!$B$28,$B$2:$B$492,"D"))+('Info Lega'!$B$7-COUNTIFS($D$2:$D$492,'Info Lega'!$B$28,$B$2:$B$492,"C"))+('Info Lega'!$B$8-COUNTIFS($D$2:$D$492,'Info Lega'!$B$28,$B$2:$B$492,"A")) -> 25 | Y6: =X6*'Parametri Modello'!$B$30 -> 25 | Z6: =MAX(0,W6-Y6) -> 975 | AA6: =MIN(F6,Z6) -> 190 | AC6: =IF($AB6="","",IF($AB6>$AA6,"PASS",IF($AB6<=$AA6*(1-'Parametri Modello'!$B$68),"BID","ATTENZIONE"))) | AD6: =IF(I6="","",ROUND(100*(1-EXP(-I6/30)),0)) -> 69 | AE6: =IFERROR(IF($AF6="Titolare",INDEX('Stato Asta'!$G$9:$G$12,MATCH($B6,'Stato Asta'!$A$9:$A$12,0)),INDEX('Stato Asta'!$P$9:$P$12,MATCH($B6,'Stato Asta'!$A$9:$A$12,0))),"") -> 🟢 Puoi aspettare | AF6: =IFERROR(IF($V6<=INDEX('Parametri Modello'!$C$57:$C$60,MATCH($B6,'Parametri Modello'!$A$57:$A$60,0)),"Titolare","Riserva"),"") -> Titolare | AG6: =IFERROR(INDEX('Pressione Competitiva'!$F$3:$F$6,MATCH($B6,'Pressione Competitiva'!$B$3:$B$6,0)),"") -> 🔴 Molto Alta | AH6: =IF($AB6="","",$AA6-$AB6) | AI6: =IFERROR(IF($AH6="","",IF($AH6>=$AA6*'Parametri Modello'!$B$68,"🟢 Opportunita'",IF($AH6<=$AA6*'Parametri Modello'!$B$69,"🔴 Sovrapprezzo","🟡 Prezzo Corretto"))),"") | AJ6: =IF($AB6="","",IF($AC6="PASS","Prezzo sopra la tua Offerta Max Dinamica ("&$AA6&" cr).",IF($AC6="BID","Margine ampio sul tuo tetto (+"&($AA6-$AB6)&" cr).","Margine ridotto: sei vicino al tuo tetto ("&($AA6-$AB6)&" cr residui)."))) | AK6: =IF(AND($D6="",$N6>1),COUNTIFS($B$2:$B$492,$B6,$P$2:$P$492,$P6,$D$2:$D$492,"",$N$2:$N$492,">1",$O$2:$O$492,">"&$O6)+1,"") -> 1 | AL6: =IF($AK6="","",$B6&"|"&$P6&"|"&$AK6) -> D|Top|1
A7: 6875 | B7: C | C7: Paz N. | E7: =IF(COUNTIF('Info Strategia'!$D$2:$D$51,$C7)>0,"SI","NO") -> NO | F7: =IFERROR(ROUND(($G7+($H7-$G7)*'Info Strategia'!$B$6)*(1+IF($E7="SI",'Parametri Modello'!$B$7*'Info Strategia'!$B$6,0)),0),"") -> 171 | G7: =IFERROR(ROUND(MAX(1,(IF($V7<=INDEX('Parametri Modello'!$C$57:$C$60,MATCH($B7,'Parametri Modello'!$A$57:$A$60,0)),IF(INDEX('Parametri Modello'!$E$57:$E$60,MATCH($B7,'Parametri Modello'!$A$57:$A$60,0))=0,0,($O7/INDEX('Parametri Modello'!$E$57:$E$60,MATCH($B7,'Parametri Modello'!$A$57:$A$60,0)))*(INDEX('Parametri Modello'!$D$57:$D$60,MATCH($B7,'Parametri Modello'!$A$57:$A$60,0))*(INDEX('Parametri Modello'!$B$50:$B$53,MATCH($B7,'Parametri Modello'!$A$50:$A$53,0))*'Parametri Modello'!$B$44))),IF(INDEX('Parametri Modello'!$F$57:$F$60,MATCH($B7,'Parametri Modello'!$A$57:$A$60,0))=0,0,($O7/INDEX('Parametri Modello'!$F$57:$F$60,MATCH($B7,'Parametri Modello'!$A$57:$A$60,0)))*((1-INDEX('Parametri Modello'!$D$57:$D$60,MATCH($B7,'Parametri Modello'!$A$57:$A$60,0)))*(INDEX('Parametri Modello'!$B$50:$B$53,MATCH($B7,'Parametri Modello'!$A$50:$A$53,0))*'Parametri Modello'!$B$44))))*(1+IF(IF($B7="D",'Info Lega'!$B$25,IF($B7="C",'Info Lega'!$B$26,"No"))="Si",'Parametri Modello'!$B$5,0))*(1+MAX(-0.25,MIN(0.25,IF(OR($T7="",$I7="",$I7=0,INDEX('Parametri Modello'!$B$19:$B$22,MATCH($B7,'Parametri Modello'!$A$19:$A$22,0))="",INDEX('Parametri Modello'!$B$19:$B$22,MATCH($B7,'Parametri Modello'!$A$19:$A$22,0))=0),0,(($T7-INDEX('Parametri Modello'!$B$19:$B$22,MATCH($B7,'Parametri Modello'!$A$19:$A$22,0)))/INDEX('Parametri Modello'!$B$19:$B$22,MATCH($B7,'Parametri Modello'!$A$19:$A$22,0)))*'Parametri Modello'!$B$9))))*(1+IF('Parametri Modello'!$B$27="Si",MAX(-'Parametri Modello'!$B$28,MIN('Parametri Modello'!$B$28*1.5,IF(OR(INDEX('Parametri Modello'!$F$32:$F$35,MATCH($B7,'Parametri Modello'!$A$32:$A$35,0))="",INDEX('Parametri Modello'!$F$32:$F$35,MATCH($B7,'Parametri Modello'!$A$32:$A$35,0))=0),0,(1/INDEX('Parametri Modello'!$F$32:$F$35,MATCH($B7,'Parametri Modello'!$A$32:$A$35,0))-1)*'Parametri Modello'!$B$28))),0)))*(1-INDEX('Parametri Modello'!$B$12:$B$15,MATCH($B7,'Parametri Modello'!$A$12:$A$15,0)))),0),"") -> 116 | H7: =IFERROR(ROUND((IF($V7<=INDEX('Parametri Modello'!$C$57:$C$60,MATCH($B7,'Parametri Modello'!$A$57:$A$60,0)),IF(INDEX('Parametri Modello'!$E$57:$E$60,MATCH($B7,'Parametri Modello'!$A$57:$A$60,0))=0,0,($O7/INDEX('Parametri Modello'!$E$57:$E$60,MATCH($B7,'Parametri Modello'!$A$57:$A$60,0)))*(INDEX('Parametri Modello'!$D$57:$D$60,MATCH($B7,'Parametri Modello'!$A$57:$A$60,0))*(INDEX('Parametri Modello'!$B$50:$B$53,MATCH($B7,'Parametri Modello'!$A$50:$A$53,0))*'Parametri Modello'!$B$44))),IF(INDEX('Parametri Modello'!$F$57:$F$60,MATCH($B7,'Parametri Modello'!$A$57:$A$60,0))=0,0,($O7/INDEX('Parametri Modello'!$F$57:$F$60,MATCH($B7,'Parametri Modello'!$A$57:$A$60,0)))*((1-INDEX('Parametri Modello'!$D$57:$D$60,MATCH($B7,'Parametri Modello'!$A$57:$A$60,0)))*(INDEX('Parametri Modello'!$B$50:$B$53,MATCH($B7,'Parametri Modello'!$A$50:$A$53,0))*'Parametri Modello'!$B$44))))*(1+IF(IF($B7="D",'Info Lega'!$B$25,IF($B7="C",'Info Lega'!$B$26,"No"))="Si",'Parametri Modello'!$B$5,0))*(1+MAX(-0.25,MIN(0.25,IF(OR($T7="",$I7="",$I7=0,INDEX('Parametri Modello'!$B$19:$B$22,MATCH($B7,'Parametri Modello'!$A$19:$A$22,0))="",INDEX('Parametri Modello'!$B$19:$B$22,MATCH($B7,'Parametri Modello'!$A$19:$A$22,0))=0),0,(($T7-INDEX('Parametri Modello'!$B$19:$B$22,MATCH($B7,'Parametri Modello'!$A$19:$A$22,0)))/INDEX('Parametri Modello'!$B$19:$B$22,MATCH($B7,'Parametri Modello'!$A$19:$A$22,0)))*'Parametri Modello'!$B$9))))*(1+IF('Parametri Modello'!$B$27="Si",MAX(-'Parametri Modello'!$B$28,MIN('Parametri Modello'!$B$28*1.5,IF(OR(INDEX('Parametri Modello'!$F$32:$F$35,MATCH($B7,'Parametri Modello'!$A$32:$A$35,0))="",INDEX('Parametri Modello'!$F$32:$F$35,MATCH($B7,'Parametri Modello'!$A$32:$A$35,0))=0),0,(1/INDEX('Parametri Modello'!$F$32:$F$35,MATCH($B7,'Parametri Modello'!$A$32:$A$35,0))-1)*'Parametri Modello'!$B$28))),0)))*(1+INDEX('Parametri Modello'!$B$12:$B$15,MATCH($B7,'Parametri Modello'!$A$12:$A$15,0))),0),"") -> 194 | I7: =IFERROR(INDEX('Input Statistiche 2025_26'!$F$3:$F$665,MATCH($A7,'Input Statistiche 2025_26'!$A$3:$A$665,0)),"") -> 35 | J7: =IFERROR(IF($I7="","",MAX(0,38-$I7)),"") -> 3 | K7: =IFERROR(INDEX('Input Statistiche 2025_26'!$I$3:$I$665,MATCH($A7,'Input Statistiche 2025_26'!$A$3:$A$665,0)),"") -> 12 | L7: =IFERROR(INDEX('Input Statistiche 2025_26'!$O$3:$O$665,MATCH($A7,'Input Statistiche 2025_26'!$A$3:$A$665,0)),"") -> 5 | N7: =IFERROR(INDEX('Input Giocatori 2026_27'!$E$3:$E$493,MATCH($A7,'Input Giocatori 2026_27'!$A$3:$A$493,0)),"") -> 30 | O7: =IFERROR(INDEX('Input Giocatori 2026_27'!$G$3:$G$493,MATCH($A7,'Input Giocatori 2026_27'!$A$3:$A$493,0)),"") -> 250 | P7: =IFERROR(IF($O7="","",IF((1-(COUNTIFS($B$2:$B$492,$B7,$O$2:$O$492,">"&$O7)+1-1)/COUNTIF($B$2:$B$492,$B7))>='Parametri Modello'!$B$63,"Top",IF((1-(COUNTIFS($B$2:$B$492,$B7,$O$2:$O$492,">"&$O7)+1-1)/COUNTIF($B$2:$B$492,$B7))>='Parametri Modello'!$B$64,"Buono",IF((1-(COUNTIFS($B$2:$B$492,$B7,$O$2:$O$492,">"&$O7)+1-1)/COUNTIF($B$2:$B$492,$B7))>='Parametri Modello'!$B$65,"Nella Media","Scommessa/Riserva")))),"") -> Top | Q7: =IF(AND($D7="",$N7>1),SUMPRODUCT(($D$2:$D7="")*($N$2:$N7>1)),"") -> 6 | R7: =IF($D7='Info Lega'!$B$28,COUNTIFS($D$2:$D7,'Info Lega'!$B$28),"") | S7: =IFERROR(INDEX('Input Statistiche 2025_26'!$G$3:$G$665,MATCH($A7,'Input Statistiche 2025_26'!$A$3:$A$665,0)),"") -> 6.37 | T7: =IFERROR(INDEX('Input Statistiche 2025_26'!$H$3:$H$665,MATCH($A7,'Input Statistiche 2025_26'!$A$3:$A$665,0)),"") -> 7.3 | U7: =IF(OR('La Mia Rosa'!$O$12="",$D7<>""),"",IF($F7<='La Mia Rosa'!$O$12*'Parametri Modello'!$B$24,"OK",IF($F7<='La Mia Rosa'!$O$12*'Parametri Modello'!$B$25,"Attenzione","Rischio Alto"))) -> Rischio Alto | V7: =IFERROR(COUNTIFS($B$2:$B$492,$B7,$O$2:$O$492,">"&$O7)+1,"") -> 1 | W7: ='Info Lega'!$B$4-SUMIFS($M$2:$M$492,$D$2:$D$492,'Info Lega'!$B$28) -> 1000 | X7: =('Info Lega'!$B$5-COUNTIFS($D$2:$D$492,'Info Lega'!$B$28,$B$2:$B$492,"P"))+('Info Lega'!$B$6-COUNTIFS($D$2:$D$492,'Info Lega'!$B$28,$B$2:$B$492,"D"))+('Info Lega'!$B$7-COUNTIFS($D$2:$D$492,'Info Lega'!$B$28,$B$2:$B$492,"C"))+('Info Lega'!$B$8-COUNTIFS($D$2:$D$492,'Info Lega'!$B$28,$B$2:$B$492,"A")) -> 25 | Y7: =X7*'Parametri Modello'!$B$30 -> 25 | Z7: =MAX(0,W7-Y7) -> 975 | AA7: =MIN(F7,Z7) -> 171 | AC7: =IF($AB7="","",IF($AB7>$AA7,"PASS",IF($AB7<=$AA7*(1-'Parametri Modello'!$B$68),"BID","ATTENZIONE"))) | AD7: =IF(I7="","",ROUND(100*(1-EXP(-I7/30)),0)) -> 69 | AE7: =IFERROR(IF($AF7="Titolare",INDEX('Stato Asta'!$G$9:$G$12,MATCH($B7,'Stato Asta'!$A$9:$A$12,0)),INDEX('Stato Asta'!$P$9:$P$12,MATCH($B7,'Stato Asta'!$A$9:$A$12,0))),"") -> 🟡 Attesa rischiosa | AF7: =IFERROR(IF($V7<=INDEX('Parametri Modello'!$C$57:$C$60,MATCH($B7,'Parametri Modello'!$A$57:$A$60,0)),"Titolare","Riserva"),"") -> Titolare | AG7: =IFERROR(INDEX('Pressione Competitiva'!$F$3:$F$6,MATCH($B7,'Pressione Competitiva'!$B$3:$B$6,0)),"") -> 🔴 Molto Alta | AH7: =IF($AB7="","",$AA7-$AB7) | AI7: =IFERROR(IF($AH7="","",IF($AH7>=$AA7*'Parametri Modello'!$B$68,"🟢 Opportunita'",IF($AH7<=$AA7*'Parametri Modello'!$B$69,"🔴 Sovrapprezzo","🟡 Prezzo Corretto"))),"") | AJ7: =IF($AB7="","",IF($AC7="PASS","Prezzo sopra la tua Offerta Max Dinamica ("&$AA7&" cr).",IF($AC7="BID","Margine ampio sul tuo tetto (+"&($AA7-$AB7)&" cr).","Margine ridotto: sei vicino al tuo tetto ("&($AA7-$AB7)&" cr residui)."))) | AK7: =IF(AND($D7="",$N7>1),COUNTIFS($B$2:$B$492,$B7,$P$2:$P$492,$P7,$D$2:$D$492,"",$N$2:$N$492,">1",$O$2:$O$492,">"&$O7)+1,"") -> 1 | AL7: =IF($AK7="","",$B7&"|"&$P7&"|"&$AK7) -> C|Top|1
